I0423 12:16:52.359927       1 serving.go:386] Generated self-signed cert in-memory
W0423 12:16:52.360549       1 client_config.go:683] Neither --kubeconfig nor --master was specified.  Using the inClusterConfig.  This might not work.
I0423 12:16:52.388108       1 scheduler.go:283] ===  SCHEDULer New  ===
I0423 12:16:52.389629       1 scheduler.go:457] "fonction New() construit le scheduler, mais ne commence pas à scheduler les pods, c'est la fonction Run() qui commence le scheduling des pods." duration ="1.488892ms"
I0423 12:16:52.391560       1 server.go:175] "Starting Kubernetes Scheduler" version="v0.0.0-master+$Format:%H$"
I0423 12:16:52.391575       1 server.go:177] "Golang settings" GOGC="" GOMAXPROCS="" GOTRACEBACK=""
I0423 12:16:52.398825       1 requestheader_controller.go:180] Starting RequestHeaderAuthRequestController
I0423 12:16:52.398850       1 shared_informer.go:375] "Waiting for caches to sync"
I0423 12:16:52.398919       1 configmap_cafile_content.go:205] "Starting controller" name="client-ca::kube-system::extension-apiserver-authentication::client-ca-file"
I0423 12:16:52.398931       1 shared_informer.go:375] "Waiting for caches to sync"
I0423 12:16:52.399084       1 secure_serving.go:211] Serving securely on [::]:10259
I0423 12:16:52.399152       1 tlsconfig.go:243] "Starting DynamicServingCertificateController"
I0423 12:16:52.400945       1 configmap_cafile_content.go:205] "Starting controller" name="client-ca::kube-system::extension-apiserver-authentication::requestheader-client-ca-file"
I0423 12:16:52.401132       1 shared_informer.go:375] "Waiting for caches to sync"
I0423 12:16:52.499330       1 shared_informer.go:382] "Caches are synced"
I0423 12:16:52.499607       1 shared_informer.go:382] "Caches are synced"
I0423 12:16:52.501863       1 shared_informer.go:382] "Caches are synced"
I0423 12:16:52.599911       1 scheduler.go:542] ===  SCHEDULing RUN ===
I0423 12:16:52.599978       1 schedule_one.go:67] === MON SCHEDULER MODIFIÉ EST EN TRAIN DE TOURNER ===
I0423 12:20:27.783287       1 schedule_one.go:67] === MON SCHEDULER MODIFIÉ EST EN TRAIN DE TOURNER ===
I0423 12:20:27.784261       1 schedule_one.go:67] === MON SCHEDULER MODIFIÉ EST EN TRAIN DE TOURNER ===
I0423 12:20:27.791015       1 schedule_one.go:166] "scheduling algorithm completed" duration ="10.841411ms" pod="default/grayscale-00001-deployment-5bdd67fc57-bf7gr"
I0423 12:20:27.792300       1 schedule_one.go:166] "scheduling algorithm completed" duration ="8.97626ms" pod="default/fastfouriertransform-00001-deployment-657cc65f49-cbq47"
I0423 12:20:27.810881       1 schedule_one.go:67] === MON SCHEDULER MODIFIÉ EST EN TRAIN DE TOURNER ===
I0423 12:20:27.814896       1 schedule_one.go:166] "scheduling algorithm completed" duration ="4.807733ms" pod="default/genmatrix-00001-deployment-5df4b84798-7jrqn"
I0423 12:20:27.828386       1 schedule_one.go:67] === MON SCHEDULER MODIFIÉ EST EN TRAIN DE TOURNER ===
I0423 12:20:27.852838       1 schedule_one.go:166] "scheduling algorithm completed" duration ="25.273812ms" pod="default/pagerank-00001-deployment-5868dc586f-qltb6"
I0423 12:20:27.858938       1 schedule_one.go:67] === MON SCHEDULER MODIFIÉ EST EN TRAIN DE TOURNER ===
I0423 12:20:27.862842       1 schedule_one.go:166] "scheduling algorithm completed" duration ="4.706991ms" pod="default/resnet-00001-deployment-58d467dc88-whznv"
I0423 12:20:28.036065       1 schedule_one.go:67] === MON SCHEDULER MODIFIÉ EST EN TRAIN DE TOURNER ===
I0423 12:20:28.041236       1 schedule_one.go:166] "scheduling algorithm completed" duration ="5.840364ms" pod="default/graphgen-00001-deployment-6f84b8d49c-gzl95"
I0423 12:20:28.313027       1 schedule_one.go:67] === MON SCHEDULER MODIFIÉ EST EN TRAIN DE TOURNER ===
I0423 12:20:28.318062       1 schedule_one.go:166] "scheduling algorithm completed" duration ="6.124328ms" pod="default/matrixmul-00001-deployment-7bd6bb5956-s76vg"
I0423 12:20:28.412378       1 schedule_one.go:67] === MON SCHEDULER MODIFIÉ EST EN TRAIN DE TOURNER ===
I0423 12:20:28.417735       1 schedule_one.go:166] "scheduling algorithm completed" duration ="6.064291ms" pod="default/linpack-00001-deployment-5786f975fd-vx9ts"
I0423 12:20:28.513134       1 schedule_one.go:67] === MON SCHEDULER MODIFIÉ EST EN TRAIN DE TOURNER ===
I0423 12:20:28.517896       1 schedule_one.go:166] "scheduling algorithm completed" duration ="5.502771ms" pod="default/mobilenet-00001-deployment-799ff7446f-sq6sj"
I0423 12:20:28.922275       1 schedule_one.go:67] === MON SCHEDULER MODIFIÉ EST EN TRAIN DE TOURNER ===
I0423 12:20:28.927711       1 schedule_one.go:166] "scheduling algorithm completed" duration ="6.232217ms" pod="default/fetchdata-00001-deployment-6f7fd5c6-ck9rf"
I0423 12:20:30.213139       1 schedule_one.go:67] === MON SCHEDULER MODIFIÉ EST EN TRAIN DE TOURNER ===
I0423 12:20:30.217418       1 schedule_one.go:166] "scheduling algorithm completed" duration ="5.225122ms" pod="default/fastfouriertransform-00001-deployment-657cc65f49-qcdpt"
I0423 12:20:30.339166       1 schedule_one.go:67] === MON SCHEDULER MODIFIÉ EST EN TRAIN DE TOURNER ===
I0423 12:20:30.351683       1 schedule_one.go:166] "scheduling algorithm completed" duration ="13.299269ms" pod="default/resnet-00001-deployment-58d467dc88-fd566"
I0423 12:20:30.462571       1 schedule_one.go:67] === MON SCHEDULER MODIFIÉ EST EN TRAIN DE TOURNER ===
I0423 12:20:30.467368       1 schedule_one.go:166] "scheduling algorithm completed" duration ="5.836938ms" pod="default/fastfouriertransform-00001-deployment-657cc65f49-tprxm"
I0423 12:20:30.513981       1 schedule_one.go:67] === MON SCHEDULER MODIFIÉ EST EN TRAIN DE TOURNER ===
I0423 12:20:30.518876       1 schedule_one.go:166] "scheduling algorithm completed" duration ="6.13668ms" pod="default/genmatrix-00001-deployment-5df4b84798-7wdcb"
I0423 12:20:30.613560       1 schedule_one.go:67] === MON SCHEDULER MODIFIÉ EST EN TRAIN DE TOURNER ===
I0423 12:20:30.618386       1 schedule_one.go:166] "scheduling algorithm completed" duration ="5.687308ms" pod="default/grayscale-00001-deployment-5bdd67fc57-z2w2l"
I0423 12:20:30.863386       1 schedule_one.go:67] === MON SCHEDULER MODIFIÉ EST EN TRAIN DE TOURNER ===
I0423 12:20:30.868038       1 schedule_one.go:166] "scheduling algorithm completed" duration ="5.374437ms" pod="default/graphgen-00001-deployment-6f84b8d49c-zhzfv"
I0423 12:20:31.113587       1 schedule_one.go:67] === MON SCHEDULER MODIFIÉ EST EN TRAIN DE TOURNER ===
I0423 12:20:31.119234       1 schedule_one.go:166] "scheduling algorithm completed" duration ="6.401458ms" pod="default/linpack-00001-deployment-5786f975fd-wf8cz"
I0423 12:20:31.512123       1 schedule_one.go:67] === MON SCHEDULER MODIFIÉ EST EN TRAIN DE TOURNER ===
I0423 12:20:31.517972       1 schedule_one.go:166] "scheduling algorithm completed" duration ="7.186478ms" pod="default/pagerank-00001-deployment-5868dc586f-fcxpp"
I0423 12:20:31.562773       1 schedule_one.go:67] === MON SCHEDULER MODIFIÉ EST EN TRAIN DE TOURNER ===
I0423 12:20:31.567299       1 schedule_one.go:166] "scheduling algorithm completed" duration ="5.916031ms" pod="default/mobilenet-00001-deployment-799ff7446f-7wts4"
I0423 12:20:31.713734       1 schedule_one.go:67] === MON SCHEDULER MODIFIÉ EST EN TRAIN DE TOURNER ===
I0423 12:20:31.719057       1 schedule_one.go:166] "scheduling algorithm completed" duration ="6.001846ms" pod="default/fetchdata-00001-deployment-6f7fd5c6-cvzrq"
I0423 12:20:32.713312       1 schedule_one.go:67] === MON SCHEDULER MODIFIÉ EST EN TRAIN DE TOURNER ===
I0423 12:20:32.718728       1 schedule_one.go:166] "scheduling algorithm completed" duration ="6.149439ms" pod="default/grayscale-00001-deployment-5bdd67fc57-56fjg"
I0423 12:20:32.813405       1 schedule_one.go:67] === MON SCHEDULER MODIFIÉ EST EN TRAIN DE TOURNER ===
I0423 12:20:32.817728       1 schedule_one.go:166] "scheduling algorithm completed" duration ="5.417049ms" pod="default/graphgen-00001-deployment-6f84b8d49c-pg86l"
I0423 12:20:32.912942       1 schedule_one.go:67] === MON SCHEDULER MODIFIÉ EST EN TRAIN DE TOURNER ===
I0423 12:20:32.917868       1 schedule_one.go:166] "scheduling algorithm completed" duration ="5.612919ms" pod="default/pagerank-00001-deployment-5868dc586f-dm65l"
I0423 12:20:33.164015       1 schedule_one.go:67] === MON SCHEDULER MODIFIÉ EST EN TRAIN DE TOURNER ===
I0423 12:20:33.169618       1 schedule_one.go:166] "scheduling algorithm completed" duration ="6.25881ms" pod="default/linpack-00001-deployment-5786f975fd-zbs5g"
I0423 12:20:33.264005       1 schedule_one.go:67] === MON SCHEDULER MODIFIÉ EST EN TRAIN DE TOURNER ===
I0423 12:20:33.268787       1 schedule_one.go:166] "scheduling algorithm completed" duration ="5.495363ms" pod="default/fetchdata-00001-deployment-6f7fd5c6-h4sdr"
I0423 12:20:33.314322       1 schedule_one.go:67] === MON SCHEDULER MODIFIÉ EST EN TRAIN DE TOURNER ===
I0423 12:20:33.318718       1 schedule_one.go:166] "scheduling algorithm completed" duration ="5.660641ms" pod="default/matrixmul-00001-deployment-7bd6bb5956-rgljp"
I0423 12:20:33.461615       1 schedule_one.go:67] === MON SCHEDULER MODIFIÉ EST EN TRAIN DE TOURNER ===
I0423 12:20:33.464738       1 schedule_one.go:166] "scheduling algorithm completed" duration ="3.728563ms" pod="default/linpack-00001-deployment-5786f975fd-k7fmk"
I0423 12:20:33.864394       1 schedule_one.go:67] === MON SCHEDULER MODIFIÉ EST EN TRAIN DE TOURNER ===
I0423 12:20:33.869444       1 schedule_one.go:166] "scheduling algorithm completed" duration ="6.005457ms" pod="default/fastfouriertransform-00001-deployment-657cc65f49-plbbb"
I0423 12:20:34.664854       1 schedule_one.go:67] === MON SCHEDULER MODIFIÉ EST EN TRAIN DE TOURNER ===
I0423 12:20:34.669860       1 schedule_one.go:166] "scheduling algorithm completed" duration ="6.159661ms" pod="default/graphgen-00001-deployment-6f84b8d49c-9cr66"
I0423 12:20:34.864816       1 schedule_one.go:67] === MON SCHEDULER MODIFIÉ EST EN TRAIN DE TOURNER ===
I0423 12:20:34.869246       1 schedule_one.go:166] "scheduling algorithm completed" duration ="5.930568ms" pod="default/resnet-00001-deployment-58d467dc88-2dp7c"
I0423 12:20:35.064959       1 schedule_one.go:67] === MON SCHEDULER MODIFIÉ EST EN TRAIN DE TOURNER ===
I0423 12:20:35.070687       1 schedule_one.go:166] "scheduling algorithm completed" duration ="6.361569ms" pod="default/matrixmul-00001-deployment-7bd6bb5956-82nhn"
I0423 12:20:35.570289       1 schedule_one.go:67] === MON SCHEDULER MODIFIÉ EST EN TRAIN DE TOURNER ===
I0423 12:20:35.574657       1 schedule_one.go:166] "scheduling algorithm completed" duration ="5.089585ms" pod="default/grayscale-00001-deployment-5bdd67fc57-jxwbs"
I0423 12:20:35.813377       1 schedule_one.go:67] === MON SCHEDULER MODIFIÉ EST EN TRAIN DE TOURNER ===
I0423 12:20:35.818578       1 schedule_one.go:166] "scheduling algorithm completed" duration ="6.161421ms" pod="default/grayscale-00001-deployment-5bdd67fc57-r9ccv"
I0423 12:20:35.865158       1 schedule_one.go:67] === MON SCHEDULER MODIFIÉ EST EN TRAIN DE TOURNER ===
I0423 12:20:35.871625       1 schedule_one.go:166] "scheduling algorithm completed" duration ="7.413701ms" pod="default/grayscale-00001-deployment-5bdd67fc57-nswd9"
I0423 12:20:35.913918       1 schedule_one.go:67] === MON SCHEDULER MODIFIÉ EST EN TRAIN DE TOURNER ===
I0423 12:20:35.918801       1 schedule_one.go:166] "scheduling algorithm completed" duration ="5.693809ms" pod="default/linpack-00001-deployment-5786f975fd-l7c6x"
I0423 12:20:36.016270       1 schedule_one.go:67] === MON SCHEDULER MODIFIÉ EST EN TRAIN DE TOURNER ===
I0423 12:20:36.021069       1 schedule_one.go:166] "scheduling algorithm completed" duration ="5.765272ms" pod="default/linpack-00001-deployment-5786f975fd-v856s"
I0423 12:20:36.363760       1 schedule_one.go:67] === MON SCHEDULER MODIFIÉ EST EN TRAIN DE TOURNER ===
I0423 12:20:36.393795       1 schedule_one.go:166] "scheduling algorithm completed" duration ="30.84849ms" pod="default/matrixmul-00001-deployment-7bd6bb5956-jgdzs"
I0423 12:20:36.414892       1 schedule_one.go:67] === MON SCHEDULER MODIFIÉ EST EN TRAIN DE TOURNER ===
I0423 12:20:36.441660       1 schedule_one.go:166] "scheduling algorithm completed" duration ="27.9268ms" pod="default/grayscale-00001-deployment-5bdd67fc57-8hn5t"
I0423 12:20:36.463247       1 schedule_one.go:67] === MON SCHEDULER MODIFIÉ EST EN TRAIN DE TOURNER ===
I0423 12:20:36.468620       1 schedule_one.go:166] "scheduling algorithm completed" duration ="6.093772ms" pod="default/linpack-00001-deployment-5786f975fd-qmbdh"
I0423 12:20:36.563289       1 schedule_one.go:67] === MON SCHEDULER MODIFIÉ EST EN TRAIN DE TOURNER ===
I0423 12:20:36.568995       1 schedule_one.go:166] "scheduling algorithm completed" duration ="6.400569ms" pod="default/grayscale-00001-deployment-5bdd67fc57-cx9m5"
I0423 12:20:36.614753       1 schedule_one.go:67] === MON SCHEDULER MODIFIÉ EST EN TRAIN DE TOURNER ===
I0423 12:20:36.620429       1 schedule_one.go:166] "scheduling algorithm completed" duration ="6.513069ms" pod="default/grayscale-00001-deployment-5bdd67fc57-mcwxn"
I0423 12:20:38.316837       1 schedule_one.go:67] === MON SCHEDULER MODIFIÉ EST EN TRAIN DE TOURNER ===
I0423 12:20:38.320696       1 schedule_one.go:166] "scheduling algorithm completed" duration ="5.950883ms" pod="default/resnet-00001-deployment-58d467dc88-z66dw"
I0423 12:20:38.815087       1 schedule_one.go:67] === MON SCHEDULER MODIFIÉ EST EN TRAIN DE TOURNER ===
I0423 12:20:38.819745       1 schedule_one.go:166] "scheduling algorithm completed" duration ="5.303862ms" pod="default/matrixmul-00001-deployment-7bd6bb5956-pgmqw"
I0423 12:20:38.864249       1 schedule_one.go:67] === MON SCHEDULER MODIFIÉ EST EN TRAIN DE TOURNER ===
I0423 12:20:38.869335       1 schedule_one.go:166] "scheduling algorithm completed" duration ="5.919235ms" pod="default/grayscale-00001-deployment-5bdd67fc57-f9t96"
I0423 12:20:39.065092       1 schedule_one.go:67] === MON SCHEDULER MODIFIÉ EST EN TRAIN DE TOURNER ===
I0423 12:20:39.070160       1 schedule_one.go:166] "scheduling algorithm completed" duration ="6.929496ms" pod="default/grayscale-00001-deployment-5bdd67fc57-nrxsp"
I0423 12:20:39.113677       1 schedule_one.go:67] === MON SCHEDULER MODIFIÉ EST EN TRAIN DE TOURNER ===
I0423 12:20:39.118557       1 schedule_one.go:166] "scheduling algorithm completed" duration ="5.600734ms" pod="default/grayscale-00001-deployment-5bdd67fc57-tp6rm"
I0423 12:20:40.268967       1 schedule_one.go:67] === MON SCHEDULER MODIFIÉ EST EN TRAIN DE TOURNER ===
I0423 12:20:40.275205       1 schedule_one.go:166] "scheduling algorithm completed" duration ="7.135533ms" pod="default/resnet-00001-deployment-58d467dc88-vh22b"
I0423 12:20:40.616155       1 schedule_one.go:67] === MON SCHEDULER MODIFIÉ EST EN TRAIN DE TOURNER ===
I0423 12:20:40.621336       1 schedule_one.go:166] "scheduling algorithm completed" duration ="6.012439ms" pod="default/grayscale-00001-deployment-5bdd67fc57-8cs8s"
I0423 12:20:40.713853       1 schedule_one.go:67] === MON SCHEDULER MODIFIÉ EST EN TRAIN DE TOURNER ===
I0423 12:20:40.719283       1 schedule_one.go:166] "scheduling algorithm completed" duration ="6.315198ms" pod="default/grayscale-00001-deployment-5bdd67fc57-2s94m"
I0423 12:20:42.132876       1 schedule_one.go:67] === MON SCHEDULER MODIFIÉ EST EN TRAIN DE TOURNER ===
I0423 12:20:42.140005       1 schedule_one.go:67] === MON SCHEDULER MODIFIÉ EST EN TRAIN DE TOURNER ===
I0423 12:20:42.140741       1 schedule_one.go:166] "scheduling algorithm completed" duration ="8.947943ms" pod="default/resnet-00001-deployment-58d467dc88-khjlq"
I0423 12:20:42.145392       1 schedule_one.go:67] === MON SCHEDULER MODIFIÉ EST EN TRAIN DE TOURNER ===
I0423 12:20:42.148227       1 schedule_one.go:166] "scheduling algorithm completed" duration ="10.572299ms" pod="default/grayscale-00001-deployment-5bdd67fc57-znvfg"
I0423 12:20:42.155259       1 schedule_one.go:166] "scheduling algorithm completed" duration ="10.50515ms" pod="default/grayscale-00001-deployment-5bdd67fc57-qv4w2"
I0423 12:20:44.136382       1 schedule_one.go:67] === MON SCHEDULER MODIFIÉ EST EN TRAIN DE TOURNER ===
I0423 12:20:44.139499       1 schedule_one.go:67] === MON SCHEDULER MODIFIÉ EST EN TRAIN DE TOURNER ===
I0423 12:20:44.143369       1 schedule_one.go:166] "scheduling algorithm completed" duration ="7.725549ms" pod="default/resnet-00001-deployment-58d467dc88-sf55r"
I0423 12:20:44.145841       1 schedule_one.go:166] "scheduling algorithm completed" duration ="7.061158ms" pod="default/grayscale-00001-deployment-5bdd67fc57-2l9g9"
I0423 12:20:46.131586       1 schedule_one.go:67] === MON SCHEDULER MODIFIÉ EST EN TRAIN DE TOURNER ===
I0423 12:20:46.137161       1 schedule_one.go:166] "scheduling algorithm completed" duration ="6.178824ms" pod="default/resnet-00001-deployment-58d467dc88-hgwx6"
I0423 12:20:48.131584       1 schedule_one.go:67] === MON SCHEDULER MODIFIÉ EST EN TRAIN DE TOURNER ===
I0423 12:20:48.136509       1 schedule_one.go:166] "scheduling algorithm completed" duration ="5.761582ms" pod="default/grayscale-00001-deployment-5bdd67fc57-mc77c"
I0423 12:26:09.547249       1 schedule_one.go:67] === MON SCHEDULER MODIFIÉ EST EN TRAIN DE TOURNER ===
I0423 12:26:09.548962       1 schedule_one.go:67] === MON SCHEDULER MODIFIÉ EST EN TRAIN DE TOURNER ===
I0423 12:26:09.553023       1 schedule_one.go:166] "scheduling algorithm completed" duration ="6.96442ms" pod="default/fastfouriertransform-00001-deployment-657cc65f49-4ftdc"
I0423 12:26:09.555974       1 schedule_one.go:166] "scheduling algorithm completed" duration ="8.39983ms" pod="default/grayscale-00001-deployment-5bdd67fc57-lj4r6"
I0423 12:26:09.595274       1 schedule_one.go:67] === MON SCHEDULER MODIFIÉ EST EN TRAIN DE TOURNER ===
I0423 12:26:09.605150       1 schedule_one.go:67] === MON SCHEDULER MODIFIÉ EST EN TRAIN DE TOURNER ===
I0423 12:26:09.607798       1 schedule_one.go:166] "scheduling algorithm completed" duration ="13.325875ms" pod="default/genmatrix-00001-deployment-5df4b84798-84fj7"
I0423 12:26:09.617505       1 schedule_one.go:166] "scheduling algorithm completed" duration ="13.412245ms" pod="default/pagerank-00001-deployment-5868dc586f-nj8xp"
I0423 12:26:09.640543       1 schedule_one.go:67] === MON SCHEDULER MODIFIÉ EST EN TRAIN DE TOURNER ===
I0423 12:26:09.646581       1 schedule_one.go:67] === MON SCHEDULER MODIFIÉ EST EN TRAIN DE TOURNER ===
I0423 12:26:09.649607       1 schedule_one.go:166] "scheduling algorithm completed" duration ="10.431926ms" pod="default/resnet-00001-deployment-58d467dc88-ls62v"
I0423 12:26:09.652097       1 schedule_one.go:166] "scheduling algorithm completed" duration ="6.451807ms" pod="default/graphgen-00001-deployment-6f84b8d49c-dd9bg"
I0423 12:26:10.072658       1 schedule_one.go:67] === MON SCHEDULER MODIFIÉ EST EN TRAIN DE TOURNER ===
I0423 12:26:10.077950       1 schedule_one.go:166] "scheduling algorithm completed" duration ="6.15377ms" pod="default/matrixmul-00001-deployment-7bd6bb5956-qkdf5"
I0423 12:26:10.472148       1 schedule_one.go:67] === MON SCHEDULER MODIFIÉ EST EN TRAIN DE TOURNER ===
I0423 12:26:10.477069       1 schedule_one.go:166] "scheduling algorithm completed" duration ="5.669565ms" pod="default/linpack-00001-deployment-5786f975fd-x8njh"
I0423 12:26:10.572544       1 schedule_one.go:67] === MON SCHEDULER MODIFIÉ EST EN TRAIN DE TOURNER ===
I0423 12:26:10.577152       1 schedule_one.go:166] "scheduling algorithm completed" duration ="5.377546ms" pod="default/mobilenet-00001-deployment-799ff7446f-ftdjj"
I0423 12:26:10.623493       1 schedule_one.go:67] === MON SCHEDULER MODIFIÉ EST EN TRAIN DE TOURNER ===
I0423 12:26:10.649892       1 schedule_one.go:166] "scheduling algorithm completed" duration ="27.258751ms" pod="default/fetchdata-00001-deployment-6f7fd5c6-88zw6"
I0423 12:26:10.770691       1 schedule_one.go:67] === MON SCHEDULER MODIFIÉ EST EN TRAIN DE TOURNER ===
I0423 12:26:10.775722       1 schedule_one.go:166] "scheduling algorithm completed" duration ="5.729418ms" pod="default/resnet-00001-deployment-58d467dc88-jkv2t"
I0423 12:26:10.972536       1 schedule_one.go:67] === MON SCHEDULER MODIFIÉ EST EN TRAIN DE TOURNER ===
I0423 12:26:10.977955       1 schedule_one.go:166] "scheduling algorithm completed" duration ="6.178696ms" pod="default/fastfouriertransform-00001-deployment-657cc65f49-8csdl"
I0423 12:26:11.024114       1 schedule_one.go:67] === MON SCHEDULER MODIFIÉ EST EN TRAIN DE TOURNER ===
I0423 12:26:11.031727       1 schedule_one.go:166] "scheduling algorithm completed" duration ="8.692274ms" pod="default/genmatrix-00001-deployment-5df4b84798-tmxgx"
I0423 12:26:12.272576       1 schedule_one.go:67] === MON SCHEDULER MODIFIÉ EST EN TRAIN DE TOURNER ===
I0423 12:26:12.277694       1 schedule_one.go:166] "scheduling algorithm completed" duration ="5.99527ms" pod="default/grayscale-00001-deployment-5bdd67fc57-rgz5z"
I0423 12:26:12.370712       1 schedule_one.go:67] === MON SCHEDULER MODIFIÉ EST EN TRAIN DE TOURNER ===
I0423 12:26:12.375456       1 schedule_one.go:166] "scheduling algorithm completed" duration ="5.421399ms" pod="default/grayscale-00001-deployment-5bdd67fc57-mjsrl"
I0423 12:26:12.421983       1 schedule_one.go:67] === MON SCHEDULER MODIFIÉ EST EN TRAIN DE TOURNER ===
I0423 12:26:12.443080       1 schedule_one.go:166] "scheduling algorithm completed" duration ="21.672648ms" pod="default/mobilenet-00001-deployment-799ff7446f-z5dk2"
I0423 12:26:12.474236       1 schedule_one.go:67] === MON SCHEDULER MODIFIÉ EST EN TRAIN DE TOURNER ===
I0423 12:26:12.479210       1 schedule_one.go:166] "scheduling algorithm completed" duration ="5.872344ms" pod="default/graphgen-00001-deployment-6f84b8d49c-g52rl"
I0423 12:26:12.576195       1 schedule_one.go:67] === MON SCHEDULER MODIFIÉ EST EN TRAIN DE TOURNER ===
I0423 12:26:12.601118       1 schedule_one.go:166] "scheduling algorithm completed" duration ="25.608377ms" pod="default/fastfouriertransform-00001-deployment-657cc65f49-6dc4n"
I0423 12:26:12.873456       1 schedule_one.go:67] === MON SCHEDULER MODIFIÉ EST EN TRAIN DE TOURNER ===
I0423 12:26:12.879110       1 schedule_one.go:166] "scheduling algorithm completed" duration ="6.28914ms" pod="default/fastfouriertransform-00001-deployment-657cc65f49-4q6fn"
I0423 12:26:13.123034       1 schedule_one.go:67] === MON SCHEDULER MODIFIÉ EST EN TRAIN DE TOURNER ===
I0423 12:26:13.127639       1 schedule_one.go:166] "scheduling algorithm completed" duration ="5.492083ms" pod="default/genmatrix-00001-deployment-5df4b84798-d6fcp"
I0423 12:26:13.320365       1 schedule_one.go:67] === MON SCHEDULER MODIFIÉ EST EN TRAIN DE TOURNER ===
I0423 12:26:13.326463       1 schedule_one.go:166] "scheduling algorithm completed" duration ="6.674734ms" pod="default/matrixmul-00001-deployment-7bd6bb5956-6kf77"
I0423 12:26:13.471556       1 schedule_one.go:67] === MON SCHEDULER MODIFIÉ EST EN TRAIN DE TOURNER ===
I0423 12:26:13.504214       1 schedule_one.go:166] "scheduling algorithm completed" duration ="33.286335ms" pod="default/pagerank-00001-deployment-5868dc586f-bnc99"
I0423 12:26:13.521315       1 schedule_one.go:67] === MON SCHEDULER MODIFIÉ EST EN TRAIN DE TOURNER ===
I0423 12:26:13.525620       1 schedule_one.go:166] "scheduling algorithm completed" duration ="4.899693ms" pod="default/linpack-00001-deployment-5786f975fd-9mpsz"
I0423 12:26:13.721881       1 schedule_one.go:67] === MON SCHEDULER MODIFIÉ EST EN TRAIN DE TOURNER ===
I0423 12:26:13.726151       1 schedule_one.go:166] "scheduling algorithm completed" duration ="5.010009ms" pod="default/fetchdata-00001-deployment-6f7fd5c6-qgnwq"
I0423 12:26:13.770698       1 schedule_one.go:67] === MON SCHEDULER MODIFIÉ EST EN TRAIN DE TOURNER ===
I0423 12:26:13.775590       1 schedule_one.go:166] "scheduling algorithm completed" duration ="5.817103ms" pod="default/pagerank-00001-deployment-5868dc586f-8hnhr"
I0423 12:26:13.821125       1 schedule_one.go:67] === MON SCHEDULER MODIFIÉ EST EN TRAIN DE TOURNER ===
I0423 12:26:13.824843       1 schedule_one.go:166] "scheduling algorithm completed" duration ="4.405304ms" pod="default/linpack-00001-deployment-5786f975fd-lkkd9"
I0423 12:26:14.972191       1 schedule_one.go:67] === MON SCHEDULER MODIFIÉ EST EN TRAIN DE TOURNER ===
I0423 12:26:14.977738       1 schedule_one.go:166] "scheduling algorithm completed" duration ="6.676308ms" pod="default/resnet-00001-deployment-58d467dc88-tvl7m"
I0423 12:26:15.125963       1 schedule_one.go:67] === MON SCHEDULER MODIFIÉ EST EN TRAIN DE TOURNER ===
I0423 12:26:15.133373       1 schedule_one.go:166] "scheduling algorithm completed" duration ="9.335683ms" pod="default/graphgen-00001-deployment-6f84b8d49c-q2dsc"
I0423 12:26:15.323707       1 schedule_one.go:67] === MON SCHEDULER MODIFIÉ EST EN TRAIN DE TOURNER ===
I0423 12:26:15.328852       1 schedule_one.go:166] "scheduling algorithm completed" duration ="6.494863ms" pod="default/linpack-00001-deployment-5786f975fd-sxbsd"
I0423 12:26:15.522258       1 schedule_one.go:67] === MON SCHEDULER MODIFIÉ EST EN TRAIN DE TOURNER ===
I0423 12:26:15.529128       1 schedule_one.go:166] "scheduling algorithm completed" duration ="7.450106ms" pod="default/grayscale-00001-deployment-5bdd67fc57-t7jqs"
I0423 12:26:16.271298       1 schedule_one.go:67] === MON SCHEDULER MODIFIÉ EST EN TRAIN DE TOURNER ===
I0423 12:26:16.278907       1 schedule_one.go:166] "scheduling algorithm completed" duration ="8.510478ms" pod="default/pagerank-00001-deployment-5868dc586f-76d7x"
I0423 12:26:16.422069       1 schedule_one.go:67] === MON SCHEDULER MODIFIÉ EST EN TRAIN DE TOURNER ===
I0423 12:26:16.428579       1 schedule_one.go:166] "scheduling algorithm completed" duration ="7.417643ms" pod="default/grayscale-00001-deployment-5bdd67fc57-wbjcw"
I0423 12:26:16.573189       1 schedule_one.go:67] === MON SCHEDULER MODIFIÉ EST EN TRAIN DE TOURNER ===
I0423 12:26:16.578433       1 schedule_one.go:166] "scheduling algorithm completed" duration ="5.865028ms" pod="default/graphgen-00001-deployment-6f84b8d49c-85d8v"
I0423 12:26:16.672051       1 schedule_one.go:67] === MON SCHEDULER MODIFIÉ EST EN TRAIN DE TOURNER ===
I0423 12:26:16.676140       1 schedule_one.go:166] "scheduling algorithm completed" duration ="4.876583ms" pod="default/fastfouriertransform-00001-deployment-657cc65f49-9xjvl"
I0423 12:26:16.723535       1 schedule_one.go:67] === MON SCHEDULER MODIFIÉ EST EN TRAIN DE TOURNER ===
I0423 12:26:16.728506       1 schedule_one.go:166] "scheduling algorithm completed" duration ="6.285677ms" pod="default/grayscale-00001-deployment-5bdd67fc57-9lk5g"
I0423 12:26:16.772767       1 schedule_one.go:67] === MON SCHEDULER MODIFIÉ EST EN TRAIN DE TOURNER ===
I0423 12:26:16.778448       1 schedule_one.go:166] "scheduling algorithm completed" duration ="6.206548ms" pod="default/matrixmul-00001-deployment-7bd6bb5956-p6wrr"
I0423 12:26:17.226022       1 schedule_one.go:67] === MON SCHEDULER MODIFIÉ EST EN TRAIN DE TOURNER ===
I0423 12:26:17.231259       1 schedule_one.go:166] "scheduling algorithm completed" duration ="6.132436ms" pod="default/linpack-00001-deployment-5786f975fd-gvxd4"
I0423 12:26:17.472340       1 schedule_one.go:67] === MON SCHEDULER MODIFIÉ EST EN TRAIN DE TOURNER ===
I0423 12:26:17.477541       1 schedule_one.go:166] "scheduling algorithm completed" duration ="5.845769ms" pod="default/linpack-00001-deployment-5786f975fd-fcsss"
I0423 12:26:18.373401       1 schedule_one.go:67] === MON SCHEDULER MODIFIÉ EST EN TRAIN DE TOURNER ===
I0423 12:26:18.378732       1 schedule_one.go:166] "scheduling algorithm completed" duration ="6.004603ms" pod="default/grayscale-00001-deployment-5bdd67fc57-vknxd"
I0423 12:26:18.422734       1 schedule_one.go:67] === MON SCHEDULER MODIFIÉ EST EN TRAIN DE TOURNER ===
I0423 12:26:18.428486       1 schedule_one.go:166] "scheduling algorithm completed" duration ="6.502678ms" pod="default/grayscale-00001-deployment-5bdd67fc57-kk2r6"
I0423 12:26:18.472368       1 schedule_one.go:67] === MON SCHEDULER MODIFIÉ EST EN TRAIN DE TOURNER ===
I0423 12:26:18.477220       1 schedule_one.go:166] "scheduling algorithm completed" duration ="5.846084ms" pod="default/grayscale-00001-deployment-5bdd67fc57-qcxf2"
I0423 12:26:20.145036       1 schedule_one.go:67] === MON SCHEDULER MODIFIÉ EST EN TRAIN DE TOURNER ===
I0423 12:26:20.147401       1 schedule_one.go:67] === MON SCHEDULER MODIFIÉ EST EN TRAIN DE TOURNER ===
I0423 12:26:20.158825       1 schedule_one.go:166] "scheduling algorithm completed" duration ="12.327503ms" pod="default/grayscale-00001-deployment-5bdd67fc57-vvbbz"
I0423 12:26:20.158877       1 schedule_one.go:166] "scheduling algorithm completed" duration ="14.581618ms" pod="default/matrixmul-00001-deployment-7bd6bb5956-4kclt"
I0423 12:26:20.159806       1 schedule_one.go:67] === MON SCHEDULER MODIFIÉ EST EN TRAIN DE TOURNER ===
I0423 12:26:20.162359       1 schedule_one.go:67] === MON SCHEDULER MODIFIÉ EST EN TRAIN DE TOURNER ===
I0423 12:26:20.170027       1 schedule_one.go:67] === MON SCHEDULER MODIFIÉ EST EN TRAIN DE TOURNER ===
I0423 12:26:20.172113       1 schedule_one.go:166] "scheduling algorithm completed" duration ="12.129299ms" pod="default/grayscale-00001-deployment-5bdd67fc57-hvx77"
I0423 12:26:20.174016       1 schedule_one.go:166] "scheduling algorithm completed" duration ="14.93121ms" pod="default/grayscale-00001-deployment-5bdd67fc57-pztns"
I0423 12:26:20.206291       1 schedule_one.go:166] "scheduling algorithm completed" duration ="37.185916ms" pod="default/grayscale-00001-deployment-5bdd67fc57-msz62"
I0423 12:26:22.150931       1 schedule_one.go:67] === MON SCHEDULER MODIFIÉ EST EN TRAIN DE TOURNER ===
I0423 12:26:22.158287       1 schedule_one.go:67] === MON SCHEDULER MODIFIÉ EST EN TRAIN DE TOURNER ===
I0423 12:26:22.158318       1 schedule_one.go:166] "scheduling algorithm completed" duration ="8.188144ms" pod="default/grayscale-00001-deployment-5bdd67fc57-c7jhr"
I0423 12:26:22.161023       1 schedule_one.go:67] === MON SCHEDULER MODIFIÉ EST EN TRAIN DE TOURNER ===
I0423 12:26:22.162994       1 schedule_one.go:166] "scheduling algorithm completed" duration ="5.413991ms" pod="default/grayscale-00001-deployment-5bdd67fc57-v45wh"
I0423 12:26:22.166152       1 schedule_one.go:166] "scheduling algorithm completed" duration ="5.838603ms" pod="default/grayscale-00001-deployment-5bdd67fc57-2fcx5"
I0423 12:26:24.127671       1 schedule_one.go:67] === MON SCHEDULER MODIFIÉ EST EN TRAIN DE TOURNER ===
I0423 12:26:24.140598       1 schedule_one.go:166] "scheduling algorithm completed" duration ="14.322506ms" pod="default/grayscale-00001-deployment-5bdd67fc57-hl5d6"
I0423 12:26:24.144209       1 schedule_one.go:67] === MON SCHEDULER MODIFIÉ EST EN TRAIN DE TOURNER ===
I0423 12:26:24.153247       1 schedule_one.go:166] "scheduling algorithm completed" duration ="11.217853ms" pod="default/resnet-00001-deployment-58d467dc88-6s428"
I0423 12:26:26.137834       1 schedule_one.go:67] === MON SCHEDULER MODIFIÉ EST EN TRAIN DE TOURNER ===
I0423 12:26:26.141246       1 schedule_one.go:67] === MON SCHEDULER MODIFIÉ EST EN TRAIN DE TOURNER ===
I0423 12:26:26.153795       1 schedule_one.go:166] "scheduling algorithm completed" duration ="17.316697ms" pod="default/resnet-00001-deployment-58d467dc88-vstwv"
I0423 12:26:26.154448       1 schedule_one.go:166] "scheduling algorithm completed" duration ="13.867839ms" pod="default/fastfouriertransform-00001-deployment-657cc65f49-wvv4c"
I0423 12:26:28.126356       1 schedule_one.go:67] === MON SCHEDULER MODIFIÉ EST EN TRAIN DE TOURNER ===
I0423 12:26:28.133388       1 schedule_one.go:67] === MON SCHEDULER MODIFIÉ EST EN TRAIN DE TOURNER ===
I0423 12:26:28.133601       1 schedule_one.go:166] "scheduling algorithm completed" duration ="7.83368ms" pod="default/resnet-00001-deployment-58d467dc88-6kl28"
I0423 12:26:28.139303       1 schedule_one.go:166] "scheduling algorithm completed" duration ="6.646493ms" pod="default/resnet-00001-deployment-58d467dc88-jnqmk"
I0423 12:46:21.139582       1 schedule_one.go:67] === MON SCHEDULER MODIFIÉ EST EN TRAIN DE TOURNER ===
I0423 12:46:21.140569       1 schedule_one.go:67] === MON SCHEDULER MODIFIÉ EST EN TRAIN DE TOURNER ===
I0423 12:46:21.150825       1 schedule_one.go:166] "scheduling algorithm completed" duration ="10.983707ms" pod="default/fastfouriertransform-00001-deployment-657cc65f49-x252b"
I0423 12:46:21.153617       1 schedule_one.go:166] "scheduling algorithm completed" duration ="15.104141ms" pod="default/grayscale-00001-deployment-5bdd67fc57-krfrv"
I0423 12:46:21.175750       1 schedule_one.go:67] === MON SCHEDULER MODIFIÉ EST EN TRAIN DE TOURNER ===
I0423 12:46:21.178118       1 schedule_one.go:67] === MON SCHEDULER MODIFIÉ EST EN TRAIN DE TOURNER ===
I0423 12:46:21.187681       1 schedule_one.go:166] "scheduling algorithm completed" duration ="12.964266ms" pod="default/genmatrix-00001-deployment-5df4b84798-dlfkv"
I0423 12:46:21.193743       1 schedule_one.go:166] "scheduling algorithm completed" duration ="16.375181ms" pod="default/pagerank-00001-deployment-5868dc586f-xtl8c"
I0423 12:46:21.224976       1 schedule_one.go:67] === MON SCHEDULER MODIFIÉ EST EN TRAIN DE TOURNER ===
I0423 12:46:21.231816       1 schedule_one.go:166] "scheduling algorithm completed" duration ="7.699923ms" pod="default/resnet-00001-deployment-58d467dc88-bkg7q"
I0423 12:46:21.320192       1 schedule_one.go:67] === MON SCHEDULER MODIFIÉ EST EN TRAIN DE TOURNER ===
I0423 12:46:21.324719       1 schedule_one.go:166] "scheduling algorithm completed" duration ="5.329955ms" pod="default/graphgen-00001-deployment-6f84b8d49c-bcgbl"
I0423 12:46:21.772307       1 schedule_one.go:67] === MON SCHEDULER MODIFIÉ EST EN TRAIN DE TOURNER ===
I0423 12:46:21.776254       1 schedule_one.go:166] "scheduling algorithm completed" duration ="4.648583ms" pod="default/matrixmul-00001-deployment-7bd6bb5956-ngzf8"
I0423 12:46:22.122576       1 schedule_one.go:67] === MON SCHEDULER MODIFIÉ EST EN TRAIN DE TOURNER ===
I0423 12:46:22.127050       1 schedule_one.go:166] "scheduling algorithm completed" duration ="5.196621ms" pod="default/linpack-00001-deployment-5786f975fd-z88wn"
I0423 12:46:22.172917       1 schedule_one.go:67] === MON SCHEDULER MODIFIÉ EST EN TRAIN DE TOURNER ===
I0423 12:46:22.177522       1 schedule_one.go:166] "scheduling algorithm completed" duration ="5.426251ms" pod="default/mobilenet-00001-deployment-799ff7446f-7z982"
I0423 12:46:22.224365       1 schedule_one.go:67] === MON SCHEDULER MODIFIÉ EST EN TRAIN DE TOURNER ===
I0423 12:46:22.248813       1 schedule_one.go:166] "scheduling algorithm completed" duration ="25.32642ms" pod="default/fetchdata-00001-deployment-6f7fd5c6-rll9b"
I0423 12:46:22.785281       1 schedule_one.go:67] === MON SCHEDULER MODIFIÉ EST EN TRAIN DE TOURNER ===
I0423 12:46:22.800587       1 schedule_one.go:166] "scheduling algorithm completed" duration ="16.143439ms" pod="default/fastfouriertransform-00001-deployment-657cc65f49-ldkp5"
I0423 12:46:23.086359       1 schedule_one.go:67] === MON SCHEDULER MODIFIÉ EST EN TRAIN DE TOURNER ===
I0423 12:46:23.101540       1 schedule_one.go:166] "scheduling algorithm completed" duration ="15.975124ms" pod="default/fastfouriertransform-00001-deployment-657cc65f49-hkfbr"
I0423 12:46:23.131707       1 schedule_one.go:67] === MON SCHEDULER MODIFIÉ EST EN TRAIN DE TOURNER ===
I0423 12:46:23.141725       1 schedule_one.go:166] "scheduling algorithm completed" duration ="10.758225ms" pod="default/grayscale-00001-deployment-5bdd67fc57-q6zp7"
I0423 12:46:23.243120       1 schedule_one.go:67] === MON SCHEDULER MODIFIÉ EST EN TRAIN DE TOURNER ===
I0423 12:46:23.255520       1 schedule_one.go:166] "scheduling algorithm completed" duration ="13.440064ms" pod="default/genmatrix-00001-deployment-5df4b84798-dj655"
I0423 12:46:23.474869       1 schedule_one.go:67] === MON SCHEDULER MODIFIÉ EST EN TRAIN DE TOURNER ===
I0423 12:46:23.480183       1 schedule_one.go:166] "scheduling algorithm completed" duration ="7.955127ms" pod="default/pagerank-00001-deployment-5868dc586f-zwgsw"
I0423 12:46:23.623937       1 schedule_one.go:67] === MON SCHEDULER MODIFIÉ EST EN TRAIN DE TOURNER ===
I0423 12:46:23.629208       1 schedule_one.go:166] "scheduling algorithm completed" duration ="6.043308ms" pod="default/resnet-00001-deployment-58d467dc88-cwq6s"
I0423 12:46:23.724242       1 schedule_one.go:67] === MON SCHEDULER MODIFIÉ EST EN TRAIN DE TOURNER ===
I0423 12:46:23.729377       1 schedule_one.go:166] "scheduling algorithm completed" duration ="6.24005ms" pod="default/linpack-00001-deployment-5786f975fd-gts4r"
I0423 12:46:24.526037       1 schedule_one.go:67] === MON SCHEDULER MODIFIÉ EST EN TRAIN DE TOURNER ===
I0423 12:46:24.532266       1 schedule_one.go:166] "scheduling algorithm completed" duration ="7.027662ms" pod="default/fastfouriertransform-00001-deployment-657cc65f49-w7j62"
I0423 12:46:24.585210       1 schedule_one.go:67] === MON SCHEDULER MODIFIÉ EST EN TRAIN DE TOURNER ===
I0423 12:46:24.590923       1 schedule_one.go:166] "scheduling algorithm completed" duration ="6.440661ms" pod="default/graphgen-00001-deployment-6f84b8d49c-kpzd7"
I0423 12:46:24.673555       1 schedule_one.go:67] === MON SCHEDULER MODIFIÉ EST EN TRAIN DE TOURNER ===
I0423 12:46:24.678562       1 schedule_one.go:166] "scheduling algorithm completed" duration ="5.6024ms" pod="default/matrixmul-00001-deployment-7bd6bb5956-jkt4j"
I0423 12:46:24.821612       1 schedule_one.go:67] === MON SCHEDULER MODIFIÉ EST EN TRAIN DE TOURNER ===
I0423 12:46:24.826615       1 schedule_one.go:166] "scheduling algorithm completed" duration ="5.641715ms" pod="default/mobilenet-00001-deployment-799ff7446f-lk4st"
I0423 12:46:25.072002       1 schedule_one.go:67] === MON SCHEDULER MODIFIÉ EST EN TRAIN DE TOURNER ===
I0423 12:46:25.078058       1 schedule_one.go:166] "scheduling algorithm completed" duration ="6.701161ms" pod="default/mobilenet-00001-deployment-799ff7446f-v4pdh"
I0423 12:46:25.122497       1 schedule_one.go:67] === MON SCHEDULER MODIFIÉ EST EN TRAIN DE TOURNER ===
I0423 12:46:25.127482       1 schedule_one.go:166] "scheduling algorithm completed" duration ="6.103919ms" pod="default/fetchdata-00001-deployment-6f7fd5c6-bpmzm"
I0423 12:46:25.671517       1 schedule_one.go:67] === MON SCHEDULER MODIFIÉ EST EN TRAIN DE TOURNER ===
I0423 12:46:25.675989       1 schedule_one.go:166] "scheduling algorithm completed" duration ="5.333918ms" pod="default/resnet-00001-deployment-58d467dc88-fz9dv"
I0423 12:46:25.721946       1 schedule_one.go:67] === MON SCHEDULER MODIFIÉ EST EN TRAIN DE TOURNER ===
I0423 12:46:25.728010       1 schedule_one.go:166] "scheduling algorithm completed" duration ="7.666497ms" pod="default/grayscale-00001-deployment-5bdd67fc57-gp7tx"
I0423 12:46:25.927618       1 schedule_one.go:67] === MON SCHEDULER MODIFIÉ EST EN TRAIN DE TOURNER ===
I0423 12:46:25.932774       1 schedule_one.go:166] "scheduling algorithm completed" duration ="8.776128ms" pod="default/linpack-00001-deployment-5786f975fd-25j8s"
I0423 12:46:26.123661       1 schedule_one.go:67] === MON SCHEDULER MODIFIÉ EST EN TRAIN DE TOURNER ===
I0423 12:46:26.129049       1 schedule_one.go:166] "scheduling algorithm completed" duration ="6.365401ms" pod="default/pagerank-00001-deployment-5868dc586f-sjlkk"
I0423 12:46:26.723030       1 schedule_one.go:67] === MON SCHEDULER MODIFIÉ EST EN TRAIN DE TOURNER ===
I0423 12:46:26.727495       1 schedule_one.go:166] "scheduling algorithm completed" duration ="7.316533ms" pod="default/graphgen-00001-deployment-6f84b8d49c-wfz8k"
I0423 12:46:27.077039       1 schedule_one.go:67] === MON SCHEDULER MODIFIÉ EST EN TRAIN DE TOURNER ===
I0423 12:46:27.083568       1 schedule_one.go:166] "scheduling algorithm completed" duration ="7.834145ms" pod="default/grayscale-00001-deployment-5bdd67fc57-4dvh4"
I0423 12:46:27.272154       1 schedule_one.go:67] === MON SCHEDULER MODIFIÉ EST EN TRAIN DE TOURNER ===
I0423 12:46:27.278841       1 schedule_one.go:166] "scheduling algorithm completed" duration ="7.479348ms" pod="default/linpack-00001-deployment-5786f975fd-jr5dk"
I0423 12:46:27.321985       1 schedule_one.go:67] === MON SCHEDULER MODIFIÉ EST EN TRAIN DE TOURNER ===
I0423 12:46:27.329071       1 schedule_one.go:166] "scheduling algorithm completed" duration ="7.855034ms" pod="default/fastfouriertransform-00001-deployment-657cc65f49-b4q4b"
I0423 12:46:27.474366       1 schedule_one.go:67] === MON SCHEDULER MODIFIÉ EST EN TRAIN DE TOURNER ===
I0423 12:46:27.483872       1 schedule_one.go:166] "scheduling algorithm completed" duration ="11.491912ms" pod="default/matrixmul-00001-deployment-7bd6bb5956-c4rl8"
I0423 12:46:27.573298       1 schedule_one.go:67] === MON SCHEDULER MODIFIÉ EST EN TRAIN DE TOURNER ===
I0423 12:46:27.585391       1 schedule_one.go:166] "scheduling algorithm completed" duration ="11.302893ms" pod="default/linpack-00001-deployment-5786f975fd-8c5cn"
I0423 12:46:28.527590       1 schedule_one.go:67] === MON SCHEDULER MODIFIÉ EST EN TRAIN DE TOURNER ===
I0423 12:46:28.538849       1 schedule_one.go:166] "scheduling algorithm completed" duration ="11.973801ms" pod="default/graphgen-00001-deployment-6f84b8d49c-lp7cq"
I0423 12:46:28.926839       1 schedule_one.go:67] === MON SCHEDULER MODIFIÉ EST EN TRAIN DE TOURNER ===
I0423 12:46:28.932315       1 schedule_one.go:166] "scheduling algorithm completed" duration ="7.180996ms" pod="default/matrixmul-00001-deployment-7bd6bb5956-q7b7l"
I0423 12:46:29.075142       1 schedule_one.go:67] === MON SCHEDULER MODIFIÉ EST EN TRAIN DE TOURNER ===
I0423 12:46:29.080856       1 schedule_one.go:166] "scheduling algorithm completed" duration ="8.206979ms" pod="default/linpack-00001-deployment-5786f975fd-zhqrl"
I0423 12:46:29.327368       1 schedule_one.go:67] === MON SCHEDULER MODIFIÉ EST EN TRAIN DE TOURNER ===
I0423 12:46:29.333020       1 schedule_one.go:166] "scheduling algorithm completed" duration ="7.126848ms" pod="default/grayscale-00001-deployment-5bdd67fc57-jwf5g"
I0423 12:46:29.521331       1 schedule_one.go:67] === MON SCHEDULER MODIFIÉ EST EN TRAIN DE TOURNER ===
I0423 12:46:29.526900       1 schedule_one.go:166] "scheduling algorithm completed" duration ="6.611772ms" pod="default/grayscale-00001-deployment-5bdd67fc57-bfr85"
I0423 12:46:30.422583       1 schedule_one.go:67] === MON SCHEDULER MODIFIÉ EST EN TRAIN DE TOURNER ===
I0423 12:46:30.429612       1 schedule_one.go:166] "scheduling algorithm completed" duration ="7.737589ms" pod="default/resnet-00001-deployment-58d467dc88-hdjml"
I0423 12:46:30.521898       1 schedule_one.go:67] === MON SCHEDULER MODIFIÉ EST EN TRAIN DE TOURNER ===
I0423 12:46:30.527103       1 schedule_one.go:166] "scheduling algorithm completed" duration ="6.447957ms" pod="default/matrixmul-00001-deployment-7bd6bb5956-s26jc"
I0423 12:46:30.822263       1 schedule_one.go:67] === MON SCHEDULER MODIFIÉ EST EN TRAIN DE TOURNER ===
I0423 12:46:30.827573       1 schedule_one.go:166] "scheduling algorithm completed" duration ="6.045735ms" pod="default/grayscale-00001-deployment-5bdd67fc57-g8424"
I0423 12:46:31.023436       1 schedule_one.go:67] === MON SCHEDULER MODIFIÉ EST EN TRAIN DE TOURNER ===
I0423 12:46:31.030412       1 schedule_one.go:166] "scheduling algorithm completed" duration ="8.036831ms" pod="default/grayscale-00001-deployment-5bdd67fc57-8lfvx"
I0423 12:46:31.071481       1 schedule_one.go:67] === MON SCHEDULER MODIFIÉ EST EN TRAIN DE TOURNER ===
I0423 12:46:31.076767       1 schedule_one.go:166] "scheduling algorithm completed" duration ="6.470531ms" pod="default/grayscale-00001-deployment-5bdd67fc57-gt47b"
I0423 12:46:31.276493       1 schedule_one.go:67] === MON SCHEDULER MODIFIÉ EST EN TRAIN DE TOURNER ===
I0423 12:46:31.282455       1 schedule_one.go:166] "scheduling algorithm completed" duration ="6.967125ms" pod="default/grayscale-00001-deployment-5bdd67fc57-6dbnm"
I0423 12:46:32.132191       1 schedule_one.go:67] === MON SCHEDULER MODIFIÉ EST EN TRAIN DE TOURNER ===
I0423 12:46:32.135384       1 schedule_one.go:67] === MON SCHEDULER MODIFIÉ EST EN TRAIN DE TOURNER ===
I0423 12:46:32.137447       1 schedule_one.go:67] === MON SCHEDULER MODIFIÉ EST EN TRAIN DE TOURNER ===
I0423 12:46:32.141388       1 schedule_one.go:166] "scheduling algorithm completed" duration ="10.217816ms" pod="default/grayscale-00001-deployment-5bdd67fc57-bm7x4"
I0423 12:46:32.145083       1 schedule_one.go:166] "scheduling algorithm completed" duration ="10.821096ms" pod="default/grayscale-00001-deployment-5bdd67fc57-shjmw"
I0423 12:46:32.147535       1 schedule_one.go:166] "scheduling algorithm completed" duration ="12.03419ms" pod="default/grayscale-00001-deployment-5bdd67fc57-7l4nt"
I0423 12:46:34.125451       1 schedule_one.go:67] === MON SCHEDULER MODIFIÉ EST EN TRAIN DE TOURNER ===
I0423 12:46:34.128695       1 schedule_one.go:67] === MON SCHEDULER MODIFIÉ EST EN TRAIN DE TOURNER ===
I0423 12:46:34.132451       1 schedule_one.go:166] "scheduling algorithm completed" duration ="8.994332ms" pod="default/grayscale-00001-deployment-5bdd67fc57-8qqbn"
I0423 12:46:34.132754       1 schedule_one.go:67] === MON SCHEDULER MODIFIÉ EST EN TRAIN DE TOURNER ===
I0423 12:46:34.138318       1 schedule_one.go:166] "scheduling algorithm completed" duration ="9.58163ms" pod="default/grayscale-00001-deployment-5bdd67fc57-hb8ms"
I0423 12:46:34.151949       1 schedule_one.go:166] "scheduling algorithm completed" duration ="24.407437ms" pod="default/grayscale-00001-deployment-5bdd67fc57-67vzl"
I0423 12:46:36.145919       1 schedule_one.go:67] === MON SCHEDULER MODIFIÉ EST EN TRAIN DE TOURNER ===
I0423 12:46:36.152818       1 schedule_one.go:166] "scheduling algorithm completed" duration ="8.08633ms" pod="default/grayscale-00001-deployment-5bdd67fc57-pf6f6"
I0423 12:46:38.135262       1 schedule_one.go:67] === MON SCHEDULER MODIFIÉ EST EN TRAIN DE TOURNER ===
I0423 12:46:38.140937       1 schedule_one.go:166] "scheduling algorithm completed" duration ="6.668717ms" pod="default/resnet-00001-deployment-58d467dc88-fn5xm"
I0423 12:46:40.129669       1 schedule_one.go:67] === MON SCHEDULER MODIFIÉ EST EN TRAIN DE TOURNER ===
I0423 12:46:40.135929       1 schedule_one.go:166] "scheduling algorithm completed" duration ="7.07257ms" pod="default/grayscale-00001-deployment-5bdd67fc57-t7w85"
I0423 12:46:40.137003       1 schedule_one.go:67] === MON SCHEDULER MODIFIÉ EST EN TRAIN DE TOURNER ===
I0423 12:46:40.143932       1 schedule_one.go:166] "scheduling algorithm completed" duration ="8.475091ms" pod="default/grayscale-00001-deployment-5bdd67fc57-fmls5"
