I0707 13:06:53.297653       1 serving.go:386] Generated self-signed cert in-memory
W0707 13:06:53.298261       1 client_config.go:683] Neither --kubeconfig nor --master was specified.  Using the inClusterConfig.  This might not work.
I0707 13:06:53.316599       1 scheduler.go:283] ===  SCHEDULer New  ===
I0707 13:06:53.318315       1 scheduler.go:457] "fonction New() construit le scheduler, mais ne commence pas à scheduler les pods, c'est la fonction Run() qui commence le scheduling des pods." duration ="1.682529ms"
I0707 13:06:53.321280       1 server.go:175] "Starting Kubernetes Scheduler" version="v0.0.0-master+$Format:%H$"
I0707 13:06:53.321302       1 server.go:177] "Golang settings" GOGC="" GOMAXPROCS="" GOTRACEBACK=""
I0707 13:06:53.325935       1 requestheader_controller.go:180] Starting RequestHeaderAuthRequestController
I0707 13:06:53.325948       1 configmap_cafile_content.go:205] "Starting controller" name="client-ca::kube-system::extension-apiserver-authentication::client-ca-file"
I0707 13:06:53.325961       1 shared_informer.go:375] "Waiting for caches to sync"
I0707 13:06:53.325969       1 shared_informer.go:375] "Waiting for caches to sync"
I0707 13:06:53.325953       1 configmap_cafile_content.go:205] "Starting controller" name="client-ca::kube-system::extension-apiserver-authentication::requestheader-client-ca-file"
I0707 13:06:53.325983       1 shared_informer.go:375] "Waiting for caches to sync"
I0707 13:06:53.326214       1 secure_serving.go:211] Serving securely on [::]:10259
I0707 13:06:53.326296       1 tlsconfig.go:243] "Starting DynamicServingCertificateController"
I0707 13:06:53.426415       1 shared_informer.go:382] "Caches are synced"
I0707 13:06:53.426415       1 shared_informer.go:382] "Caches are synced"
I0707 13:06:53.426583       1 shared_informer.go:382] "Caches are synced"
I0707 13:06:53.626873       1 scheduler.go:542] ===  SCHEDULing RUN ===
I0707 13:06:53.626922       1 schedule_one.go:67] === MON SCHEDULER MODIFIÉ EST EN TRAIN DE TOURNER ===
I0707 14:38:30.023581       1 schedule_one.go:67] === MON SCHEDULER MODIFIÉ EST EN TRAIN DE TOURNER ===
I0707 14:38:30.032880       1 schedule_one.go:67] === MON SCHEDULER MODIFIÉ EST EN TRAIN DE TOURNER ===
I0707 14:38:30.033292       1 schedule_one.go:166] "scheduling algorithm completed" duration ="11.142576ms" pod="default/resnet-00001-deployment-5687dd4f7c-jkjdk"
I0707 14:38:30.035985       1 schedule_one.go:67] === MON SCHEDULER MODIFIÉ EST EN TRAIN DE TOURNER ===
I0707 14:38:30.048346       1 schedule_one.go:166] "scheduling algorithm completed" duration ="15.954235ms" pod="default/mobilenet-00001-deployment-855b8bc6bc-lrxc4"
I0707 14:38:30.050668       1 schedule_one.go:67] === MON SCHEDULER MODIFIÉ EST EN TRAIN DE TOURNER ===
I0707 14:38:30.061819       1 schedule_one.go:166] "scheduling algorithm completed" duration ="26.326117ms" pod="default/mobilenet-00001-deployment-855b8bc6bc-f6ftx"
I0707 14:38:30.074097       1 schedule_one.go:166] "scheduling algorithm completed" duration ="24.004964ms" pod="default/resnet-00001-deployment-5687dd4f7c-dw99x"
I0707 14:38:31.386393       1 schedule_one.go:67] === MON SCHEDULER MODIFIÉ EST EN TRAIN DE TOURNER ===
I0707 14:38:31.395947       1 schedule_one.go:67] === MON SCHEDULER MODIFIÉ EST EN TRAIN DE TOURNER ===
I0707 14:38:31.396900       1 schedule_one.go:166] "scheduling algorithm completed" duration ="11.060889ms" pod="default/mobilenet-00001-deployment-855b8bc6bc-n7rnt"
I0707 14:38:31.412164       1 schedule_one.go:166] "scheduling algorithm completed" duration ="17.082764ms" pod="default/resnet-00001-deployment-5687dd4f7c-5zslr"
I0707 14:38:31.415543       1 schedule_one.go:67] === MON SCHEDULER MODIFIÉ EST EN TRAIN DE TOURNER ===
I0707 14:38:31.417692       1 schedule_one.go:67] === MON SCHEDULER MODIFIÉ EST EN TRAIN DE TOURNER ===
I0707 14:38:31.421537       1 schedule_one.go:67] === MON SCHEDULER MODIFIÉ EST EN TRAIN DE TOURNER ===
I0707 14:38:31.435854       1 schedule_one.go:67] === MON SCHEDULER MODIFIÉ EST EN TRAIN DE TOURNER ===
I0707 14:38:31.453681       1 schedule_one.go:166] "scheduling algorithm completed" duration ="38.694464ms" pod="default/mobilenet-00001-deployment-855b8bc6bc-rqwvb"
I0707 14:38:31.454771       1 schedule_one.go:166] "scheduling algorithm completed" duration ="19.432085ms" pod="default/resnet-00001-deployment-5687dd4f7c-89f7n"
I0707 14:38:31.455813       1 schedule_one.go:67] === MON SCHEDULER MODIFIÉ EST EN TRAIN DE TOURNER ===
I0707 14:38:31.476516       1 schedule_one.go:67] === MON SCHEDULER MODIFIÉ EST EN TRAIN DE TOURNER ===
I0707 14:38:31.486659       1 schedule_one.go:166] "scheduling algorithm completed" duration ="65.606717ms" pod="default/mobilenet-00001-deployment-855b8bc6bc-25q4q"
I0707 14:38:31.494946       1 schedule_one.go:67] === MON SCHEDULER MODIFIÉ EST EN TRAIN DE TOURNER ===
I0707 14:38:31.496230       1 schedule_one.go:67] === MON SCHEDULER MODIFIÉ EST EN TRAIN DE TOURNER ===
I0707 14:38:31.501600       1 schedule_one.go:67] === MON SCHEDULER MODIFIÉ EST EN TRAIN DE TOURNER ===
I0707 14:38:31.534143       1 schedule_one.go:166] "scheduling algorithm completed" duration ="79.6681ms" pod="default/mobilenet-00001-deployment-855b8bc6bc-dv5g9"
I0707 14:38:31.534865       1 schedule_one.go:166] "scheduling algorithm completed" duration ="58.897297ms" pod="default/mobilenet-00001-deployment-855b8bc6bc-4vm2m"
I0707 14:38:31.591001       1 schedule_one.go:166] "scheduling algorithm completed" duration ="95.393517ms" pod="default/resnet-00001-deployment-5687dd4f7c-mbxcz"
I0707 14:38:31.608095       1 schedule_one.go:166] "scheduling algorithm completed" duration ="190.901961ms" pod="default/resnet-00001-deployment-5687dd4f7c-p9rkw"
I0707 14:38:31.608937       1 schedule_one.go:166] "scheduling algorithm completed" duration ="114.672434ms" pod="default/mobilenet-00001-deployment-855b8bc6bc-7mx46"
I0707 14:38:31.673580       1 schedule_one.go:166] "scheduling algorithm completed" duration ="172.504794ms" pod="default/resnet-00001-deployment-5687dd4f7c-whbbk"
I0707 14:38:33.414622       1 schedule_one.go:67] === MON SCHEDULER MODIFIÉ EST EN TRAIN DE TOURNER ===
I0707 14:38:33.422015       1 schedule_one.go:166] "scheduling algorithm completed" duration ="8.032414ms" pod="default/mobilenet-00001-deployment-855b8bc6bc-895wm"
I0707 14:38:33.441309       1 schedule_one.go:67] === MON SCHEDULER MODIFIÉ EST EN TRAIN DE TOURNER ===
I0707 14:38:33.455107       1 schedule_one.go:166] "scheduling algorithm completed" duration ="14.789335ms" pod="default/mobilenet-00001-deployment-855b8bc6bc-xg9cl"
I0707 14:38:33.457595       1 schedule_one.go:67] === MON SCHEDULER MODIFIÉ EST EN TRAIN DE TOURNER ===
I0707 14:38:33.468056       1 schedule_one.go:166] "scheduling algorithm completed" duration ="11.038185ms" pod="default/resnet-00001-deployment-5687dd4f7c-qlpd7"
I0707 14:38:33.490425       1 schedule_one.go:67] === MON SCHEDULER MODIFIÉ EST EN TRAIN DE TOURNER ===
I0707 14:38:33.495836       1 schedule_one.go:67] === MON SCHEDULER MODIFIÉ EST EN TRAIN DE TOURNER ===
I0707 14:38:33.506516       1 schedule_one.go:166] "scheduling algorithm completed" duration ="16.808262ms" pod="default/resnet-00001-deployment-5687dd4f7c-pmrdw"
I0707 14:38:33.533507       1 schedule_one.go:166] "scheduling algorithm completed" duration ="39.991199ms" pod="default/resnet-00001-deployment-5687dd4f7c-tp9v2"
I0707 14:38:35.491932       1 schedule_one.go:67] === MON SCHEDULER MODIFIÉ EST EN TRAIN DE TOURNER ===
I0707 14:38:35.578938       1 schedule_one.go:166] "scheduling algorithm completed" duration ="87.675995ms" pod="default/mobilenet-00001-deployment-855b8bc6bc-z2qv8"
I0707 14:38:35.848275       1 schedule_one.go:67] === MON SCHEDULER MODIFIÉ EST EN TRAIN DE TOURNER ===
I0707 14:38:35.870324       1 schedule_one.go:166] "scheduling algorithm completed" duration ="22.855212ms" pod="default/resnet-00001-deployment-5687dd4f7c-wpn7w"
I0707 14:38:35.995059       1 schedule_one.go:67] === MON SCHEDULER MODIFIÉ EST EN TRAIN DE TOURNER ===
I0707 14:38:36.015422       1 schedule_one.go:67] === MON SCHEDULER MODIFIÉ EST EN TRAIN DE TOURNER ===
I0707 14:38:36.047203       1 schedule_one.go:166] "scheduling algorithm completed" duration ="32.740219ms" pod="default/resnet-00001-deployment-5687dd4f7c-4zzh8"
I0707 14:38:36.052496       1 schedule_one.go:166] "scheduling algorithm completed" duration ="59.349543ms" pod="default/resnet-00001-deployment-5687dd4f7c-ngq7b"
I0707 14:38:36.097063       1 schedule_one.go:67] === MON SCHEDULER MODIFIÉ EST EN TRAIN DE TOURNER ===
I0707 14:38:36.099730       1 schedule_one.go:67] === MON SCHEDULER MODIFIÉ EST EN TRAIN DE TOURNER ===
I0707 14:38:36.101296       1 schedule_one.go:67] === MON SCHEDULER MODIFIÉ EST EN TRAIN DE TOURNER ===
I0707 14:38:36.102306       1 schedule_one.go:67] === MON SCHEDULER MODIFIÉ EST EN TRAIN DE TOURNER ===
I0707 14:38:36.153809       1 schedule_one.go:67] === MON SCHEDULER MODIFIÉ EST EN TRAIN DE TOURNER ===
I0707 14:38:36.209045       1 schedule_one.go:166] "scheduling algorithm completed" duration ="112.886935ms" pod="default/resnet-00001-deployment-5687dd4f7c-rvsdf"
I0707 14:38:36.209517       1 schedule_one.go:166] "scheduling algorithm completed" duration ="108.182813ms" pod="default/resnet-00001-deployment-5687dd4f7c-ng5js"
I0707 14:38:36.210120       1 schedule_one.go:166] "scheduling algorithm completed" duration ="111.302511ms" pod="default/resnet-00001-deployment-5687dd4f7c-dnqz7"
I0707 14:38:36.210473       1 schedule_one.go:166] "scheduling algorithm completed" duration ="109.826552ms" pod="default/resnet-00001-deployment-5687dd4f7c-xzrmz"
I0707 14:38:36.253764       1 schedule_one.go:166] "scheduling algorithm completed" duration ="100.842035ms" pod="default/resnet-00001-deployment-5687dd4f7c-24j7z"
I0707 14:38:37.417238       1 schedule_one.go:67] === MON SCHEDULER MODIFIÉ EST EN TRAIN DE TOURNER ===
I0707 14:38:37.456466       1 schedule_one.go:166] "scheduling algorithm completed" duration ="40.173591ms" pod="default/resnet-00001-deployment-5687dd4f7c-g55l5"
I0707 14:38:37.471463       1 schedule_one.go:67] === MON SCHEDULER MODIFIÉ EST EN TRAIN DE TOURNER ===
I0707 14:38:37.473214       1 schedule_one.go:67] === MON SCHEDULER MODIFIÉ EST EN TRAIN DE TOURNER ===
I0707 14:38:37.506723       1 schedule_one.go:166] "scheduling algorithm completed" duration ="34.09101ms" pod="default/resnet-00001-deployment-5687dd4f7c-qr4nl"
I0707 14:38:37.507234       1 schedule_one.go:166] "scheduling algorithm completed" duration ="36.690018ms" pod="default/resnet-00001-deployment-5687dd4f7c-gl8np"
I0707 14:38:37.525338       1 schedule_one.go:67] === MON SCHEDULER MODIFIÉ EST EN TRAIN DE TOURNER ===
I0707 14:38:37.527291       1 schedule_one.go:67] === MON SCHEDULER MODIFIÉ EST EN TRAIN DE TOURNER ===
I0707 14:38:37.551263       1 schedule_one.go:166] "scheduling algorithm completed" duration ="24.813731ms" pod="default/resnet-00001-deployment-5687dd4f7c-zvd5g"
I0707 14:38:37.568204       1 schedule_one.go:166] "scheduling algorithm completed" duration ="43.606495ms" pod="default/resnet-00001-deployment-5687dd4f7c-fstnz"
I0707 14:38:39.412786       1 schedule_one.go:67] === MON SCHEDULER MODIFIÉ EST EN TRAIN DE TOURNER ===
I0707 14:38:39.431035       1 schedule_one.go:166] "scheduling algorithm completed" duration ="19.120489ms" pod="default/resnet-00001-deployment-5687dd4f7c-fw92f"
I0707 14:38:39.462052       1 schedule_one.go:67] === MON SCHEDULER MODIFIÉ EST EN TRAIN DE TOURNER ===
I0707 14:38:39.497650       1 schedule_one.go:166] "scheduling algorithm completed" duration ="36.171013ms" pod="default/resnet-00001-deployment-5687dd4f7c-9cz5x"
I0707 14:38:39.499853       1 schedule_one.go:67] === MON SCHEDULER MODIFIÉ EST EN TRAIN DE TOURNER ===
I0707 14:38:39.518893       1 schedule_one.go:166] "scheduling algorithm completed" duration ="19.746828ms" pod="default/resnet-00001-deployment-5687dd4f7c-ndfgv"
I0707 14:38:39.538171       1 schedule_one.go:67] === MON SCHEDULER MODIFIÉ EST EN TRAIN DE TOURNER ===
I0707 14:38:39.563745       1 schedule_one.go:166] "scheduling algorithm completed" duration ="26.326451ms" pod="default/resnet-00001-deployment-5687dd4f7c-w7z25"
I0707 14:38:41.473570       1 schedule_one.go:67] === MON SCHEDULER MODIFIÉ EST EN TRAIN DE TOURNER ===
I0707 14:38:41.516176       1 schedule_one.go:166] "scheduling algorithm completed" duration ="43.538698ms" pod="default/resnet-00001-deployment-5687dd4f7c-mlrh7"
