I0520 10:44:21.911670       1 serving.go:386] Generated self-signed cert in-memory
W0520 10:44:21.912287       1 client_config.go:683] Neither --kubeconfig nor --master was specified.  Using the inClusterConfig.  This might not work.
I0520 10:44:21.936533       1 scheduler.go:283] ===  SCHEDULer New  ===
I0520 10:44:21.938042       1 scheduler.go:457] "fonction New() construit le scheduler, mais ne commence pas à scheduler les pods, c'est la fonction Run() qui commence le scheduling des pods." duration ="1.481057ms"
I0520 10:44:21.940400       1 server.go:175] "Starting Kubernetes Scheduler" version="v0.0.0-master+$Format:%H$"
I0520 10:44:21.940432       1 server.go:177] "Golang settings" GOGC="" GOMAXPROCS="" GOTRACEBACK=""
I0520 10:44:21.947415       1 requestheader_controller.go:180] Starting RequestHeaderAuthRequestController
I0520 10:44:21.947434       1 shared_informer.go:375] "Waiting for caches to sync"
I0520 10:44:21.947472       1 configmap_cafile_content.go:205] "Starting controller" name="client-ca::kube-system::extension-apiserver-authentication::requestheader-client-ca-file"
I0520 10:44:21.947487       1 shared_informer.go:375] "Waiting for caches to sync"
I0520 10:44:21.947504       1 configmap_cafile_content.go:205] "Starting controller" name="client-ca::kube-system::extension-apiserver-authentication::client-ca-file"
I0520 10:44:21.947532       1 shared_informer.go:375] "Waiting for caches to sync"
I0520 10:44:21.947645       1 secure_serving.go:211] Serving securely on [::]:10259
I0520 10:44:21.947707       1 tlsconfig.go:243] "Starting DynamicServingCertificateController"
I0520 10:44:22.048468       1 shared_informer.go:382] "Caches are synced"
I0520 10:44:22.048640       1 shared_informer.go:382] "Caches are synced"
I0520 10:44:22.048674       1 shared_informer.go:382] "Caches are synced"
I0520 10:44:22.148598       1 scheduler.go:542] ===  SCHEDULing RUN ===
I0520 10:44:22.148660       1 schedule_one.go:67] === MON SCHEDULER MODIFIÉ EST EN TRAIN DE TOURNER ===
I0520 11:01:12.929506       1 schedule_one.go:67] === MON SCHEDULER MODIFIÉ EST EN TRAIN DE TOURNER ===
I0520 11:01:12.930457       1 schedule_one.go:67] === MON SCHEDULER MODIFIÉ EST EN TRAIN DE TOURNER ===
I0520 11:01:12.933727       1 schedule_one.go:166] "scheduling algorithm completed" duration ="6.076505ms" pod="default/mobilenet-00001-deployment-84db65c7f9-tb5gh"
I0520 11:01:12.935310       1 schedule_one.go:166] "scheduling algorithm completed" duration ="5.770524ms" pod="default/resnet-00001-deployment-5697b6d685-dp57l"
I0520 11:01:14.705556       1 schedule_one.go:67] === MON SCHEDULER MODIFIÉ EST EN TRAIN DE TOURNER ===
I0520 11:01:14.712218       1 schedule_one.go:67] === MON SCHEDULER MODIFIÉ EST EN TRAIN DE TOURNER ===
I0520 11:01:14.713318       1 schedule_one.go:67] === MON SCHEDULER MODIFIÉ EST EN TRAIN DE TOURNER ===
I0520 11:01:14.714625       1 schedule_one.go:166] "scheduling algorithm completed" duration ="9.660639ms" pod="default/mobilenet-00001-deployment-84db65c7f9-tzw8l"
I0520 11:01:14.716441       1 schedule_one.go:67] === MON SCHEDULER MODIFIÉ EST EN TRAIN DE TOURNER ===
I0520 11:01:14.717350       1 schedule_one.go:67] === MON SCHEDULER MODIFIÉ EST EN TRAIN DE TOURNER ===
I0520 11:01:14.718579       1 schedule_one.go:67] === MON SCHEDULER MODIFIÉ EST EN TRAIN DE TOURNER ===
I0520 11:01:14.718943       1 schedule_one.go:166] "scheduling algorithm completed" duration ="7.495193ms" pod="default/resnet-00001-deployment-5697b6d685-vksvn"
I0520 11:01:14.723099       1 schedule_one.go:67] === MON SCHEDULER MODIFIÉ EST EN TRAIN DE TOURNER ===
I0520 11:01:14.728000       1 schedule_one.go:166] "scheduling algorithm completed" duration ="15.747367ms" pod="default/mobilenet-00001-deployment-84db65c7f9-hzmw2"
I0520 11:01:14.728393       1 schedule_one.go:67] === MON SCHEDULER MODIFIÉ EST EN TRAIN DE TOURNER ===
I0520 11:01:14.732822       1 schedule_one.go:166] "scheduling algorithm completed" duration ="16.35159ms" pod="default/resnet-00001-deployment-5697b6d685-nvwl4"
I0520 11:01:14.734257       1 schedule_one.go:67] === MON SCHEDULER MODIFIÉ EST EN TRAIN DE TOURNER ===
I0520 11:01:14.736277       1 schedule_one.go:67] === MON SCHEDULER MODIFIÉ EST EN TRAIN DE TOURNER ===
I0520 11:01:14.737616       1 schedule_one.go:166] "scheduling algorithm completed" duration ="22.01628ms" pod="default/mobilenet-00001-deployment-84db65c7f9-pztqc"
I0520 11:01:14.739464       1 schedule_one.go:67] === MON SCHEDULER MODIFIÉ EST EN TRAIN DE TOURNER ===
I0520 11:01:14.740218       1 schedule_one.go:67] === MON SCHEDULER MODIFIÉ EST EN TRAIN DE TOURNER ===
I0520 11:01:14.740975       1 schedule_one.go:166] "scheduling algorithm completed" duration ="23.352596ms" pod="default/resnet-00001-deployment-5697b6d685-sj6bs"
I0520 11:01:14.741039       1 schedule_one.go:166] "scheduling algorithm completed" duration ="18.549907ms" pod="default/mobilenet-00001-deployment-84db65c7f9-jppcd"
I0520 11:01:14.744272       1 schedule_one.go:166] "scheduling algorithm completed" duration ="16.521979ms" pod="default/resnet-00001-deployment-5697b6d685-ccncj"
I0520 11:01:14.747173       1 schedule_one.go:166] "scheduling algorithm completed" duration ="14.193588ms" pod="default/mobilenet-00001-deployment-84db65c7f9-pqg29"
I0520 11:01:14.747229       1 schedule_one.go:166] "scheduling algorithm completed" duration ="9.444861ms" pod="default/resnet-00001-deployment-5697b6d685-tbjgh"
I0520 11:01:14.759029       1 schedule_one.go:166] "scheduling algorithm completed" duration ="23.737356ms" pod="default/resnet-00001-deployment-5697b6d685-kbj85"
I0520 11:01:14.761994       1 schedule_one.go:166] "scheduling algorithm completed" duration ="22.502503ms" pod="default/mobilenet-00001-deployment-84db65c7f9-t9zlp"
I0520 11:01:16.708704       1 schedule_one.go:67] === MON SCHEDULER MODIFIÉ EST EN TRAIN DE TOURNER ===
I0520 11:01:16.711687       1 schedule_one.go:67] === MON SCHEDULER MODIFIÉ EST EN TRAIN DE TOURNER ===
I0520 11:01:16.714619       1 schedule_one.go:166] "scheduling algorithm completed" duration ="6.696506ms" pod="default/mobilenet-00001-deployment-84db65c7f9-7tn64"
I0520 11:01:16.715053       1 schedule_one.go:67] === MON SCHEDULER MODIFIÉ EST EN TRAIN DE TOURNER ===
I0520 11:01:16.718651       1 schedule_one.go:67] === MON SCHEDULER MODIFIÉ EST EN TRAIN DE TOURNER ===
I0520 11:01:16.719654       1 schedule_one.go:67] === MON SCHEDULER MODIFIÉ EST EN TRAIN DE TOURNER ===
I0520 11:01:16.720671       1 schedule_one.go:166] "scheduling algorithm completed" duration ="9.972177ms" pod="default/resnet-00001-deployment-5697b6d685-7wbk2"
I0520 11:01:16.721073       1 schedule_one.go:67] === MON SCHEDULER MODIFIÉ EST EN TRAIN DE TOURNER ===
I0520 11:01:16.722419       1 schedule_one.go:166] "scheduling algorithm completed" duration ="8.112156ms" pod="default/mobilenet-00001-deployment-84db65c7f9-qj7pp"
I0520 11:01:16.725828       1 schedule_one.go:166] "scheduling algorithm completed" duration ="7.806137ms" pod="default/mobilenet-00001-deployment-84db65c7f9-qwm2b"
I0520 11:01:16.726163       1 schedule_one.go:166] "scheduling algorithm completed" duration ="7.187914ms" pod="default/resnet-00001-deployment-5697b6d685-rn5tc"
I0520 11:01:16.726633       1 schedule_one.go:67] === MON SCHEDULER MODIFIÉ EST EN TRAIN DE TOURNER ===
I0520 11:01:16.728215       1 schedule_one.go:166] "scheduling algorithm completed" duration ="7.880934ms" pod="default/resnet-00001-deployment-5697b6d685-n88hm"
I0520 11:01:16.739996       1 schedule_one.go:166] "scheduling algorithm completed" duration ="14.176532ms" pod="default/mobilenet-00001-deployment-84db65c7f9-gq8gr"
I0520 11:01:18.709711       1 schedule_one.go:67] === MON SCHEDULER MODIFIÉ EST EN TRAIN DE TOURNER ===
I0520 11:01:18.720173       1 schedule_one.go:166] "scheduling algorithm completed" duration ="11.441011ms" pod="default/resnet-00001-deployment-5697b6d685-rq5l9"
I0520 11:01:18.720346       1 schedule_one.go:67] === MON SCHEDULER MODIFIÉ EST EN TRAIN DE TOURNER ===
I0520 11:01:18.728072       1 schedule_one.go:67] === MON SCHEDULER MODIFIÉ EST EN TRAIN DE TOURNER ===
I0520 11:01:18.733188       1 schedule_one.go:67] === MON SCHEDULER MODIFIÉ EST EN TRAIN DE TOURNER ===
I0520 11:01:18.741445       1 schedule_one.go:166] "scheduling algorithm completed" duration ="21.962706ms" pod="default/resnet-00001-deployment-5697b6d685-j779l"
I0520 11:01:18.748619       1 schedule_one.go:67] === MON SCHEDULER MODIFIÉ EST EN TRAIN DE TOURNER ===
I0520 11:01:18.749780       1 schedule_one.go:166] "scheduling algorithm completed" duration ="22.677947ms" pod="default/mobilenet-00001-deployment-84db65c7f9-dpwhl"
I0520 11:01:18.750773       1 schedule_one.go:67] === MON SCHEDULER MODIFIÉ EST EN TRAIN DE TOURNER ===
I0520 11:01:18.750870       1 schedule_one.go:166] "scheduling algorithm completed" duration ="18.411054ms" pod="default/resnet-00001-deployment-5697b6d685-hpl8w"
I0520 11:01:18.755263       1 schedule_one.go:166] "scheduling algorithm completed" duration ="8.180526ms" pod="default/resnet-00001-deployment-5697b6d685-s57w5"
I0520 11:01:18.759765       1 schedule_one.go:166] "scheduling algorithm completed" duration ="11.105918ms" pod="default/resnet-00001-deployment-5697b6d685-8sphr"
I0520 11:01:20.704423       1 schedule_one.go:67] === MON SCHEDULER MODIFIÉ EST EN TRAIN DE TOURNER ===
I0520 11:01:20.707869       1 schedule_one.go:67] === MON SCHEDULER MODIFIÉ EST EN TRAIN DE TOURNER ===
I0520 11:01:20.709257       1 schedule_one.go:166] "scheduling algorithm completed" duration ="6.362691ms" pod="default/resnet-00001-deployment-5697b6d685-8b9hr"
I0520 11:01:20.710552       1 schedule_one.go:67] === MON SCHEDULER MODIFIÉ EST EN TRAIN DE TOURNER ===
I0520 11:01:20.713520       1 schedule_one.go:67] === MON SCHEDULER MODIFIÉ EST EN TRAIN DE TOURNER ===
I0520 11:01:20.713570       1 schedule_one.go:166] "scheduling algorithm completed" duration ="6.649099ms" pod="default/resnet-00001-deployment-5697b6d685-7mxg6"
I0520 11:01:20.714427       1 schedule_one.go:67] === MON SCHEDULER MODIFIÉ EST EN TRAIN DE TOURNER ===
I0520 11:01:20.716161       1 schedule_one.go:67] === MON SCHEDULER MODIFIÉ EST EN TRAIN DE TOURNER ===
I0520 11:01:20.716639       1 schedule_one.go:166] "scheduling algorithm completed" duration ="7.734192ms" pod="default/resnet-00001-deployment-5697b6d685-gcnv2"
I0520 11:01:20.720684       1 schedule_one.go:166] "scheduling algorithm completed" duration ="7.115118ms" pod="default/resnet-00001-deployment-5697b6d685-t8x8z"
I0520 11:01:20.722545       1 schedule_one.go:166] "scheduling algorithm completed" duration ="10.129102ms" pod="default/resnet-00001-deployment-5697b6d685-sn98l"
I0520 11:01:20.724961       1 schedule_one.go:166] "scheduling algorithm completed" duration ="9.822176ms" pod="default/resnet-00001-deployment-5697b6d685-5js2v"
I0520 11:01:22.706506       1 schedule_one.go:67] === MON SCHEDULER MODIFIÉ EST EN TRAIN DE TOURNER ===
I0520 11:01:22.712284       1 schedule_one.go:67] === MON SCHEDULER MODIFIÉ EST EN TRAIN DE TOURNER ===
I0520 11:01:22.712843       1 schedule_one.go:166] "scheduling algorithm completed" duration ="7.628841ms" pod="default/resnet-00001-deployment-5697b6d685-jwnnr"
I0520 11:01:22.716198       1 schedule_one.go:67] === MON SCHEDULER MODIFIÉ EST EN TRAIN DE TOURNER ===
I0520 11:01:22.718552       1 schedule_one.go:67] === MON SCHEDULER MODIFIÉ EST EN TRAIN DE TOURNER ===
I0520 11:01:22.720301       1 schedule_one.go:67] === MON SCHEDULER MODIFIÉ EST EN TRAIN DE TOURNER ===
I0520 11:01:22.721793       1 schedule_one.go:166] "scheduling algorithm completed" duration ="11.380937ms" pod="default/resnet-00001-deployment-5697b6d685-vtwwd"
I0520 11:01:22.723363       1 schedule_one.go:166] "scheduling algorithm completed" duration ="11.03501ms" pod="default/resnet-00001-deployment-5697b6d685-89krl"
I0520 11:01:22.726199       1 schedule_one.go:166] "scheduling algorithm completed" duration ="9.941584ms" pod="default/resnet-00001-deployment-5697b6d685-pxwvl"
I0520 11:01:22.728811       1 schedule_one.go:166] "scheduling algorithm completed" duration ="10.18938ms" pod="default/resnet-00001-deployment-5697b6d685-qswlr"
I0520 11:01:24.709790       1 schedule_one.go:67] === MON SCHEDULER MODIFIÉ EST EN TRAIN DE TOURNER ===
I0520 11:01:24.716619       1 schedule_one.go:67] === MON SCHEDULER MODIFIÉ EST EN TRAIN DE TOURNER ===
I0520 11:01:24.716996       1 schedule_one.go:166] "scheduling algorithm completed" duration ="8.071842ms" pod="default/resnet-00001-deployment-5697b6d685-xj65p"
I0520 11:01:24.718872       1 schedule_one.go:67] === MON SCHEDULER MODIFIÉ EST EN TRAIN DE TOURNER ===
I0520 11:01:24.721548       1 schedule_one.go:166] "scheduling algorithm completed" duration ="6.745802ms" pod="default/resnet-00001-deployment-5697b6d685-4npvf"
I0520 11:01:24.725665       1 schedule_one.go:166] "scheduling algorithm completed" duration ="9.005731ms" pod="default/resnet-00001-deployment-5697b6d685-ndl48"
I0520 11:10:49.503866       1 schedule_one.go:67] === MON SCHEDULER MODIFIÉ EST EN TRAIN DE TOURNER ===
I0520 11:10:49.504874       1 schedule_one.go:67] === MON SCHEDULER MODIFIÉ EST EN TRAIN DE TOURNER ===
I0520 11:10:49.509259       1 schedule_one.go:166] "scheduling algorithm completed" duration ="6.698636ms" pod="default/resnet-00001-deployment-5697b6d685-fd5jn"
I0520 11:10:49.512570       1 schedule_one.go:166] "scheduling algorithm completed" duration ="8.67336ms" pod="default/mobilenet-00001-deployment-84db65c7f9-nkkf5"
I0520 11:10:50.701803       1 schedule_one.go:67] === MON SCHEDULER MODIFIÉ EST EN TRAIN DE TOURNER ===
I0520 11:10:50.710077       1 schedule_one.go:67] === MON SCHEDULER MODIFIÉ EST EN TRAIN DE TOURNER ===
I0520 11:10:50.711260       1 schedule_one.go:67] === MON SCHEDULER MODIFIÉ EST EN TRAIN DE TOURNER ===
I0520 11:10:50.711804       1 schedule_one.go:166] "scheduling algorithm completed" duration ="10.541159ms" pod="default/mobilenet-00001-deployment-84db65c7f9-v4tt7"
I0520 11:10:50.714428       1 schedule_one.go:67] === MON SCHEDULER MODIFIÉ EST EN TRAIN DE TOURNER ===
I0520 11:10:50.715087       1 schedule_one.go:166] "scheduling algorithm completed" duration ="4.378912ms" pod="default/mobilenet-00001-deployment-84db65c7f9-5lgjl"
I0520 11:10:50.715383       1 schedule_one.go:67] === MON SCHEDULER MODIFIÉ EST EN TRAIN DE TOURNER ===
I0520 11:10:50.715817       1 schedule_one.go:166] "scheduling algorithm completed" duration ="6.30471ms" pod="default/mobilenet-00001-deployment-84db65c7f9-5gzkk"
I0520 11:10:50.720993       1 schedule_one.go:67] === MON SCHEDULER MODIFIÉ EST EN TRAIN DE TOURNER ===
I0520 11:10:50.721568       1 schedule_one.go:166] "scheduling algorithm completed" duration ="8.057064ms" pod="default/mobilenet-00001-deployment-84db65c7f9-d2hjh"
I0520 11:10:50.722688       1 schedule_one.go:166] "scheduling algorithm completed" duration ="8.232341ms" pod="default/mobilenet-00001-deployment-84db65c7f9-kplfg"
I0520 11:10:50.729130       1 schedule_one.go:67] === MON SCHEDULER MODIFIÉ EST EN TRAIN DE TOURNER ===
I0520 11:10:50.733477       1 schedule_one.go:166] "scheduling algorithm completed" duration ="13.05592ms" pod="default/resnet-00001-deployment-5697b6d685-9z8db"
I0520 11:10:50.733733       1 schedule_one.go:67] === MON SCHEDULER MODIFIÉ EST EN TRAIN DE TOURNER ===
I0520 11:10:50.746505       1 schedule_one.go:67] === MON SCHEDULER MODIFIÉ EST EN TRAIN DE TOURNER ===
I0520 11:10:50.746874       1 schedule_one.go:166] "scheduling algorithm completed" duration ="18.313758ms" pod="default/resnet-00001-deployment-5697b6d685-mptw4"
I0520 11:10:50.747138       1 schedule_one.go:166] "scheduling algorithm completed" duration ="14.033699ms" pod="default/resnet-00001-deployment-5697b6d685-wvgsl"
I0520 11:10:50.757059       1 schedule_one.go:166] "scheduling algorithm completed" duration ="11.08064ms" pod="default/resnet-00001-deployment-5697b6d685-fpp28"
I0520 11:10:52.708328       1 schedule_one.go:67] === MON SCHEDULER MODIFIÉ EST EN TRAIN DE TOURNER ===
I0520 11:10:52.709987       1 schedule_one.go:67] === MON SCHEDULER MODIFIÉ EST EN TRAIN DE TOURNER ===
I0520 11:10:52.713081       1 schedule_one.go:67] === MON SCHEDULER MODIFIÉ EST EN TRAIN DE TOURNER ===
I0520 11:10:52.714956       1 schedule_one.go:166] "scheduling algorithm completed" duration ="8.274674ms" pod="default/mobilenet-00001-deployment-84db65c7f9-nz9dh"
I0520 11:10:52.715805       1 schedule_one.go:67] === MON SCHEDULER MODIFIÉ EST EN TRAIN DE TOURNER ===
I0520 11:10:52.716687       1 schedule_one.go:166] "scheduling algorithm completed" duration ="8.3066ms" pod="default/resnet-00001-deployment-5697b6d685-dczb4"
I0520 11:10:52.716969       1 schedule_one.go:67] === MON SCHEDULER MODIFIÉ EST EN TRAIN DE TOURNER ===
I0520 11:10:52.718750       1 schedule_one.go:67] === MON SCHEDULER MODIFIÉ EST EN TRAIN DE TOURNER ===
I0520 11:10:52.720256       1 schedule_one.go:166] "scheduling algorithm completed" duration ="8.425212ms" pod="default/mobilenet-00001-deployment-84db65c7f9-ww8np"
I0520 11:10:52.720426       1 schedule_one.go:166] "scheduling algorithm completed" duration ="6.687524ms" pod="default/mobilenet-00001-deployment-84db65c7f9-p84s7"
I0520 11:10:52.722824       1 schedule_one.go:166] "scheduling algorithm completed" duration ="6.986562ms" pod="default/resnet-00001-deployment-5697b6d685-blnpb"
I0520 11:10:52.726301       1 schedule_one.go:166] "scheduling algorithm completed" duration ="8.403934ms" pod="default/resnet-00001-deployment-5697b6d685-rnwmm"
I0520 11:10:52.726543       1 schedule_one.go:67] === MON SCHEDULER MODIFIÉ EST EN TRAIN DE TOURNER ===
I0520 11:10:52.738375       1 schedule_one.go:166] "scheduling algorithm completed" duration ="12.811178ms" pod="default/resnet-00001-deployment-5697b6d685-7gwz8"
I0520 11:10:54.702462       1 schedule_one.go:67] === MON SCHEDULER MODIFIÉ EST EN TRAIN DE TOURNER ===
I0520 11:10:54.705005       1 schedule_one.go:67] === MON SCHEDULER MODIFIÉ EST EN TRAIN DE TOURNER ===
I0520 11:10:54.707694       1 schedule_one.go:67] === MON SCHEDULER MODIFIÉ EST EN TRAIN DE TOURNER ===
I0520 11:10:54.714686       1 schedule_one.go:166] "scheduling algorithm completed" duration ="13.18292ms" pod="default/resnet-00001-deployment-5697b6d685-g6nfn"
I0520 11:10:54.718377       1 schedule_one.go:166] "scheduling algorithm completed" duration ="13.975272ms" pod="default/resnet-00001-deployment-5697b6d685-7szwn"
I0520 11:10:54.723321       1 schedule_one.go:166] "scheduling algorithm completed" duration ="17.483794ms" pod="default/resnet-00001-deployment-5697b6d685-5ftjf"
I0520 11:10:54.726849       1 schedule_one.go:67] === MON SCHEDULER MODIFIÉ EST EN TRAIN DE TOURNER ===
I0520 11:10:54.728298       1 schedule_one.go:67] === MON SCHEDULER MODIFIÉ EST EN TRAIN DE TOURNER ===
I0520 11:10:54.729190       1 schedule_one.go:67] === MON SCHEDULER MODIFIÉ EST EN TRAIN DE TOURNER ===
I0520 11:10:54.730897       1 schedule_one.go:67] === MON SCHEDULER MODIFIÉ EST EN TRAIN DE TOURNER ===
I0520 11:10:54.733154       1 schedule_one.go:166] "scheduling algorithm completed" duration ="7.98123ms" pod="default/resnet-00001-deployment-5697b6d685-tz687"
I0520 11:10:54.734048       1 schedule_one.go:166] "scheduling algorithm completed" duration ="7.160451ms" pod="default/resnet-00001-deployment-5697b6d685-kqhnm"
I0520 11:10:54.737538       1 schedule_one.go:166] "scheduling algorithm completed" duration ="9.134175ms" pod="default/resnet-00001-deployment-5697b6d685-2lsjm"
I0520 11:10:54.739735       1 schedule_one.go:166] "scheduling algorithm completed" duration ="9.658584ms" pod="default/resnet-00001-deployment-5697b6d685-7zxr8"
I0520 11:10:56.730513       1 schedule_one.go:67] === MON SCHEDULER MODIFIÉ EST EN TRAIN DE TOURNER ===
I0520 11:10:56.736644       1 schedule_one.go:166] "scheduling algorithm completed" duration ="6.793469ms" pod="default/resnet-00001-deployment-5697b6d685-4x824"
I0520 11:10:56.740072       1 schedule_one.go:67] === MON SCHEDULER MODIFIÉ EST EN TRAIN DE TOURNER ===
I0520 11:10:56.744504       1 schedule_one.go:67] === MON SCHEDULER MODIFIÉ EST EN TRAIN DE TOURNER ===
I0520 11:10:56.745138       1 schedule_one.go:166] "scheduling algorithm completed" duration ="8.079804ms" pod="default/resnet-00001-deployment-5697b6d685-f4lzj"
I0520 11:10:56.748313       1 schedule_one.go:166] "scheduling algorithm completed" duration ="8.118729ms" pod="default/resnet-00001-deployment-5697b6d685-wsctp"
I0520 11:10:56.754636       1 schedule_one.go:67] === MON SCHEDULER MODIFIÉ EST EN TRAIN DE TOURNER ===
I0520 11:10:56.755922       1 schedule_one.go:67] === MON SCHEDULER MODIFIÉ EST EN TRAIN DE TOURNER ===
I0520 11:10:56.757230       1 schedule_one.go:67] === MON SCHEDULER MODIFIÉ EST EN TRAIN DE TOURNER ===
I0520 11:10:56.761527       1 schedule_one.go:166] "scheduling algorithm completed" duration ="7.715304ms" pod="default/resnet-00001-deployment-5697b6d685-j45nz"
I0520 11:10:56.762809       1 schedule_one.go:166] "scheduling algorithm completed" duration ="7.512285ms" pod="default/resnet-00001-deployment-5697b6d685-jgwpk"
I0520 11:10:56.769526       1 schedule_one.go:67] === MON SCHEDULER MODIFIÉ EST EN TRAIN DE TOURNER ===
I0520 11:10:56.773983       1 schedule_one.go:166] "scheduling algorithm completed" duration ="15.224051ms" pod="default/resnet-00001-deployment-5697b6d685-6pkrt"
I0520 11:10:56.776371       1 schedule_one.go:166] "scheduling algorithm completed" duration ="20.346834ms" pod="default/resnet-00001-deployment-5697b6d685-kt8mw"
I0520 11:10:58.707183       1 schedule_one.go:67] === MON SCHEDULER MODIFIÉ EST EN TRAIN DE TOURNER ===
I0520 11:10:58.710448       1 schedule_one.go:67] === MON SCHEDULER MODIFIÉ EST EN TRAIN DE TOURNER ===
I0520 11:10:58.711811       1 schedule_one.go:67] === MON SCHEDULER MODIFIÉ EST EN TRAIN DE TOURNER ===
I0520 11:10:58.712809       1 schedule_one.go:166] "scheduling algorithm completed" duration ="7.247081ms" pod="default/resnet-00001-deployment-5697b6d685-kffdx"
I0520 11:10:58.714408       1 schedule_one.go:166] "scheduling algorithm completed" duration ="6.078913ms" pod="default/resnet-00001-deployment-5697b6d685-d45h6"
I0520 11:10:58.717017       1 schedule_one.go:67] === MON SCHEDULER MODIFIÉ EST EN TRAIN DE TOURNER ===
I0520 11:10:58.717679       1 schedule_one.go:166] "scheduling algorithm completed" duration ="6.806265ms" pod="default/resnet-00001-deployment-5697b6d685-8pqks"
I0520 11:10:58.720832       1 schedule_one.go:166] "scheduling algorithm completed" duration ="4.540652ms" pod="default/resnet-00001-deployment-5697b6d685-xx5jp"
I0520 11:11:00.704594       1 schedule_one.go:67] === MON SCHEDULER MODIFIÉ EST EN TRAIN DE TOURNER ===
I0520 11:11:00.709774       1 schedule_one.go:166] "scheduling algorithm completed" duration ="6.339913ms" pod="default/resnet-00001-deployment-5697b6d685-2hdbc"
I0520 11:20:16.162549       1 schedule_one.go:67] === MON SCHEDULER MODIFIÉ EST EN TRAIN DE TOURNER ===
I0520 11:20:16.164358       1 schedule_one.go:67] === MON SCHEDULER MODIFIÉ EST EN TRAIN DE TOURNER ===
I0520 11:20:16.168443       1 schedule_one.go:166] "scheduling algorithm completed" duration ="6.566099ms" pod="default/mobilenet-00001-deployment-84db65c7f9-cdqwk"
I0520 11:20:16.171118       1 schedule_one.go:166] "scheduling algorithm completed" duration ="7.261803ms" pod="default/resnet-00001-deployment-5697b6d685-gl2wm"
I0520 11:20:16.720654       1 schedule_one.go:67] === MON SCHEDULER MODIFIÉ EST EN TRAIN DE TOURNER ===
I0520 11:20:16.724945       1 schedule_one.go:166] "scheduling algorithm completed" duration ="4.857116ms" pod="default/mobilenet-00001-deployment-84db65c7f9-nlhzp"
I0520 11:20:18.713368       1 schedule_one.go:67] === MON SCHEDULER MODIFIÉ EST EN TRAIN DE TOURNER ===
I0520 11:20:18.717250       1 schedule_one.go:67] === MON SCHEDULER MODIFIÉ EST EN TRAIN DE TOURNER ===
I0520 11:20:18.721253       1 schedule_one.go:67] === MON SCHEDULER MODIFIÉ EST EN TRAIN DE TOURNER ===
I0520 11:20:18.722498       1 schedule_one.go:166] "scheduling algorithm completed" duration ="5.925653ms" pod="default/resnet-00001-deployment-5697b6d685-v6vs4"
I0520 11:20:18.724687       1 schedule_one.go:67] === MON SCHEDULER MODIFIÉ EST EN TRAIN DE TOURNER ===
I0520 11:20:18.725536       1 schedule_one.go:166] "scheduling algorithm completed" duration ="13.037549ms" pod="default/resnet-00001-deployment-5697b6d685-x7kh6"
I0520 11:20:18.727808       1 schedule_one.go:67] === MON SCHEDULER MODIFIÉ EST EN TRAIN DE TOURNER ===
I0520 11:20:18.728618       1 schedule_one.go:67] === MON SCHEDULER MODIFIÉ EST EN TRAIN DE TOURNER ===
I0520 11:20:18.730392       1 schedule_one.go:67] === MON SCHEDULER MODIFIÉ EST EN TRAIN DE TOURNER ===
I0520 11:20:18.731288       1 schedule_one.go:67] === MON SCHEDULER MODIFIÉ EST EN TRAIN DE TOURNER ===
I0520 11:20:18.731618       1 schedule_one.go:166] "scheduling algorithm completed" duration ="11.090529ms" pod="default/resnet-00001-deployment-5697b6d685-gpznl"
I0520 11:20:18.733093       1 schedule_one.go:67] === MON SCHEDULER MODIFIÉ EST EN TRAIN DE TOURNER ===
I0520 11:20:18.734178       1 schedule_one.go:166] "scheduling algorithm completed" duration ="10.837955ms" pod="default/mobilenet-00001-deployment-84db65c7f9-bcs7s"
I0520 11:20:18.735600       1 schedule_one.go:166] "scheduling algorithm completed" duration ="8.650675ms" pod="default/resnet-00001-deployment-5697b6d685-85flf"
I0520 11:20:18.736620       1 schedule_one.go:166] "scheduling algorithm completed" duration ="8.778564ms" pod="default/resnet-00001-deployment-5697b6d685-vkzk4"
I0520 11:20:18.738599       1 schedule_one.go:166] "scheduling algorithm completed" duration ="9.130898ms" pod="default/resnet-00001-deployment-5697b6d685-v2nc2"
I0520 11:20:18.740907       1 schedule_one.go:67] === MON SCHEDULER MODIFIÉ EST EN TRAIN DE TOURNER ===
I0520 11:20:18.743686       1 schedule_one.go:67] === MON SCHEDULER MODIFIÉ EST EN TRAIN DE TOURNER ===
I0520 11:20:18.743856       1 schedule_one.go:166] "scheduling algorithm completed" duration ="13.429216ms" pod="default/mobilenet-00001-deployment-84db65c7f9-hwd84"
I0520 11:20:18.750296       1 schedule_one.go:166] "scheduling algorithm completed" duration ="18.215073ms" pod="default/mobilenet-00001-deployment-84db65c7f9-nbxcw"
I0520 11:20:18.764644       1 schedule_one.go:166] "scheduling algorithm completed" duration ="24.829801ms" pod="default/mobilenet-00001-deployment-84db65c7f9-dfgrh"
I0520 11:20:18.778858       1 schedule_one.go:166] "scheduling algorithm completed" duration ="36.194553ms" pod="default/mobilenet-00001-deployment-84db65c7f9-f94rc"
I0520 11:20:20.738842       1 schedule_one.go:67] === MON SCHEDULER MODIFIÉ EST EN TRAIN DE TOURNER ===
I0520 11:20:20.742601       1 schedule_one.go:67] === MON SCHEDULER MODIFIÉ EST EN TRAIN DE TOURNER ===
I0520 11:20:20.744782       1 schedule_one.go:67] === MON SCHEDULER MODIFIÉ EST EN TRAIN DE TOURNER ===
I0520 11:20:20.745291       1 schedule_one.go:166] "scheduling algorithm completed" duration ="7.081173ms" pod="default/resnet-00001-deployment-5697b6d685-5cq84"
I0520 11:20:20.748846       1 schedule_one.go:67] === MON SCHEDULER MODIFIÉ EST EN TRAIN DE TOURNER ===
I0520 11:20:20.750921       1 schedule_one.go:67] === MON SCHEDULER MODIFIÉ EST EN TRAIN DE TOURNER ===
I0520 11:20:20.751607       1 schedule_one.go:166] "scheduling algorithm completed" duration ="9.630342ms" pod="default/resnet-00001-deployment-5697b6d685-qbsx5"
I0520 11:20:20.752368       1 schedule_one.go:67] === MON SCHEDULER MODIFIÉ EST EN TRAIN DE TOURNER ===
I0520 11:20:20.752900       1 schedule_one.go:166] "scheduling algorithm completed" duration ="8.749545ms" pod="default/resnet-00001-deployment-5697b6d685-d4lsg"
I0520 11:20:20.754343       1 schedule_one.go:166] "scheduling algorithm completed" duration ="6.095617ms" pod="default/resnet-00001-deployment-5697b6d685-dklp4"
I0520 11:20:20.759015       1 schedule_one.go:166] "scheduling algorithm completed" duration ="7.376118ms" pod="default/resnet-00001-deployment-5697b6d685-7c5m9"
I0520 11:20:20.762999       1 schedule_one.go:166] "scheduling algorithm completed" duration ="12.616548ms" pod="default/resnet-00001-deployment-5697b6d685-ls64m"
I0520 11:20:22.720626       1 schedule_one.go:67] === MON SCHEDULER MODIFIÉ EST EN TRAIN DE TOURNER ===
I0520 11:20:22.726316       1 schedule_one.go:166] "scheduling algorithm completed" duration ="6.532636ms" pod="default/resnet-00001-deployment-5697b6d685-gwmd7"
I0520 11:20:22.727290       1 schedule_one.go:67] === MON SCHEDULER MODIFIÉ EST EN TRAIN DE TOURNER ===
I0520 11:20:22.729615       1 schedule_one.go:67] === MON SCHEDULER MODIFIÉ EST EN TRAIN DE TOURNER ===
I0520 11:20:22.734319       1 schedule_one.go:166] "scheduling algorithm completed" duration ="8.061823ms" pod="default/resnet-00001-deployment-5697b6d685-9sxxn"
I0520 11:20:22.735683       1 schedule_one.go:166] "scheduling algorithm completed" duration ="6.925006ms" pod="default/resnet-00001-deployment-5697b6d685-v4wpx"
I0520 11:20:22.736045       1 schedule_one.go:67] === MON SCHEDULER MODIFIÉ EST EN TRAIN DE TOURNER ===
I0520 11:20:22.738045       1 schedule_one.go:67] === MON SCHEDULER MODIFIÉ EST EN TRAIN DE TOURNER ===
I0520 11:20:22.738931       1 schedule_one.go:67] === MON SCHEDULER MODIFIÉ EST EN TRAIN DE TOURNER ===
I0520 11:20:22.740158       1 schedule_one.go:67] === MON SCHEDULER MODIFIÉ EST EN TRAIN DE TOURNER ===
I0520 11:20:22.741406       1 schedule_one.go:67] === MON SCHEDULER MODIFIÉ EST EN TRAIN DE TOURNER ===
I0520 11:20:22.742753       1 schedule_one.go:166] "scheduling algorithm completed" duration ="8.869508ms" pod="default/resnet-00001-deployment-5697b6d685-zfpsr"
I0520 11:20:22.743596       1 schedule_one.go:166] "scheduling algorithm completed" duration ="7.021914ms" pod="default/resnet-00001-deployment-5697b6d685-v6mzd"
I0520 11:20:22.745041       1 schedule_one.go:166] "scheduling algorithm completed" duration ="6.959136ms" pod="default/resnet-00001-deployment-5697b6d685-ns4jk"
I0520 11:20:22.746346       1 schedule_one.go:166] "scheduling algorithm completed" duration ="7.385784ms" pod="default/resnet-00001-deployment-5697b6d685-8b9cp"
I0520 11:20:22.746525       1 schedule_one.go:67] === MON SCHEDULER MODIFIÉ EST EN TRAIN DE TOURNER ===
I0520 11:20:22.748459       1 schedule_one.go:166] "scheduling algorithm completed" duration ="7.806637ms" pod="default/resnet-00001-deployment-5697b6d685-v7q58"
I0520 11:20:22.760037       1 schedule_one.go:166] "scheduling algorithm completed" duration ="15.933663ms" pod="default/resnet-00001-deployment-5697b6d685-gblf6"
I0520 11:20:24.715325       1 schedule_one.go:67] === MON SCHEDULER MODIFIÉ EST EN TRAIN DE TOURNER ===
I0520 11:20:24.720328       1 schedule_one.go:67] === MON SCHEDULER MODIFIÉ EST EN TRAIN DE TOURNER ===
I0520 11:20:24.721486       1 schedule_one.go:166] "scheduling algorithm completed" duration ="7.103988ms" pod="default/resnet-00001-deployment-5697b6d685-ljlgc"
I0520 11:20:24.725015       1 schedule_one.go:67] === MON SCHEDULER MODIFIÉ EST EN TRAIN DE TOURNER ===
I0520 11:20:24.726093       1 schedule_one.go:166] "scheduling algorithm completed" duration ="6.452636ms" pod="default/resnet-00001-deployment-5697b6d685-p68zc"
I0520 11:20:24.726697       1 schedule_one.go:67] === MON SCHEDULER MODIFIÉ EST EN TRAIN DE TOURNER ===
I0520 11:20:24.727556       1 schedule_one.go:67] === MON SCHEDULER MODIFIÉ EST EN TRAIN DE TOURNER ===
I0520 11:20:24.731908       1 schedule_one.go:166] "scheduling algorithm completed" duration ="11.5399ms" pod="default/resnet-00001-deployment-5697b6d685-2g949"
I0520 11:20:24.732704       1 schedule_one.go:166] "scheduling algorithm completed" duration ="7.650711ms" pod="default/resnet-00001-deployment-5697b6d685-d68jr"
I0520 11:20:24.737270       1 schedule_one.go:166] "scheduling algorithm completed" duration ="10.538713ms" pod="default/resnet-00001-deployment-5697b6d685-jg97w"
I0520 11:20:26.721107       1 schedule_one.go:67] === MON SCHEDULER MODIFIÉ EST EN TRAIN DE TOURNER ===
I0520 11:20:26.729759       1 schedule_one.go:166] "scheduling algorithm completed" duration ="9.340972ms" pod="default/resnet-00001-deployment-5697b6d685-kvdjz"
I0520 11:30:17.739106       1 schedule_one.go:67] === MON SCHEDULER MODIFIÉ EST EN TRAIN DE TOURNER ===
I0520 11:30:17.740141       1 schedule_one.go:67] === MON SCHEDULER MODIFIÉ EST EN TRAIN DE TOURNER ===
I0520 11:30:17.745598       1 schedule_one.go:166] "scheduling algorithm completed" duration ="7.205507ms" pod="default/resnet-00001-deployment-5697b6d685-clwqq"
I0520 11:30:17.747243       1 schedule_one.go:166] "scheduling algorithm completed" duration ="7.607136ms" pod="default/mobilenet-00001-deployment-84db65c7f9-s24jb"
I0520 11:30:18.716066       1 schedule_one.go:67] === MON SCHEDULER MODIFIÉ EST EN TRAIN DE TOURNER ===
I0520 11:30:18.719599       1 schedule_one.go:67] === MON SCHEDULER MODIFIÉ EST EN TRAIN DE TOURNER ===
I0520 11:30:18.722100       1 schedule_one.go:67] === MON SCHEDULER MODIFIÉ EST EN TRAIN DE TOURNER ===
I0520 11:30:18.722765       1 schedule_one.go:166] "scheduling algorithm completed" duration ="7.470988ms" pod="default/mobilenet-00001-deployment-84db65c7f9-bpc9j"
I0520 11:30:18.723281       1 schedule_one.go:67] === MON SCHEDULER MODIFIÉ EST EN TRAIN DE TOURNER ===
I0520 11:30:18.725378       1 schedule_one.go:67] === MON SCHEDULER MODIFIÉ EST EN TRAIN DE TOURNER ===
I0520 11:30:18.728167       1 schedule_one.go:67] === MON SCHEDULER MODIFIÉ EST EN TRAIN DE TOURNER ===
I0520 11:30:18.729005       1 schedule_one.go:67] === MON SCHEDULER MODIFIÉ EST EN TRAIN DE TOURNER ===
I0520 11:30:18.729013       1 schedule_one.go:166] "scheduling algorithm completed" duration ="10.144158ms" pod="default/resnet-00001-deployment-5697b6d685-9gg9f"
I0520 11:30:18.730460       1 schedule_one.go:166] "scheduling algorithm completed" duration ="9.119138ms" pod="default/mobilenet-00001-deployment-84db65c7f9-pkc9l"
I0520 11:30:18.733099       1 schedule_one.go:67] === MON SCHEDULER MODIFIÉ EST EN TRAIN DE TOURNER ===
I0520 11:30:18.733267       1 schedule_one.go:166] "scheduling algorithm completed" duration ="10.923788ms" pod="default/mobilenet-00001-deployment-84db65c7f9-g55pn"
I0520 11:30:18.733348       1 schedule_one.go:166] "scheduling algorithm completed" duration ="8.751267ms" pod="default/resnet-00001-deployment-5697b6d685-9sfvp"
I0520 11:30:18.734475       1 schedule_one.go:166] "scheduling algorithm completed" duration ="7.144988ms" pod="default/resnet-00001-deployment-5697b6d685-kjrn7"
I0520 11:30:18.740093       1 schedule_one.go:166] "scheduling algorithm completed" duration ="11.889714ms" pod="default/mobilenet-00001-deployment-84db65c7f9-vqxmm"
I0520 11:30:18.759850       1 schedule_one.go:166] "scheduling algorithm completed" duration ="28.140248ms" pod="default/resnet-00001-deployment-5697b6d685-fp6s5"
I0520 11:30:20.718627       1 schedule_one.go:67] === MON SCHEDULER MODIFIÉ EST EN TRAIN DE TOURNER ===
I0520 11:30:20.721220       1 schedule_one.go:67] === MON SCHEDULER MODIFIÉ EST EN TRAIN DE TOURNER ===
I0520 11:30:20.725198       1 schedule_one.go:67] === MON SCHEDULER MODIFIÉ EST EN TRAIN DE TOURNER ===
I0520 11:30:20.726560       1 schedule_one.go:166] "scheduling algorithm completed" duration ="8.898861ms" pod="default/resnet-00001-deployment-5697b6d685-klv8k"
I0520 11:30:20.729867       1 schedule_one.go:67] === MON SCHEDULER MODIFIÉ EST EN TRAIN DE TOURNER ===
I0520 11:30:20.731662       1 schedule_one.go:67] === MON SCHEDULER MODIFIÉ EST EN TRAIN DE TOURNER ===
I0520 11:30:20.733926       1 schedule_one.go:166] "scheduling algorithm completed" duration ="14.165995ms" pod="default/mobilenet-00001-deployment-84db65c7f9-4qf8w"
I0520 11:30:20.733962       1 schedule_one.go:166] "scheduling algorithm completed" duration ="9.593472ms" pod="default/resnet-00001-deployment-5697b6d685-bq5st"
I0520 11:30:20.733978       1 schedule_one.go:67] === MON SCHEDULER MODIFIÉ EST EN TRAIN DE TOURNER ===
I0520 11:30:20.735685       1 schedule_one.go:67] === MON SCHEDULER MODIFIÉ EST EN TRAIN DE TOURNER ===
I0520 11:30:20.737208       1 schedule_one.go:166] "scheduling algorithm completed" duration ="8.305656ms" pod="default/resnet-00001-deployment-5697b6d685-6vc4t"
I0520 11:30:20.738569       1 schedule_one.go:166] "scheduling algorithm completed" duration ="5.674523ms" pod="default/mobilenet-00001-deployment-84db65c7f9-xlfcf"
I0520 11:30:20.738809       1 schedule_one.go:166] "scheduling algorithm completed" duration ="7.963396ms" pod="default/mobilenet-00001-deployment-84db65c7f9-jd79x"
I0520 11:30:20.739509       1 schedule_one.go:166] "scheduling algorithm completed" duration ="4.643412ms" pod="default/resnet-00001-deployment-5697b6d685-p75wq"
I0520 11:30:20.761546       1 schedule_one.go:67] === MON SCHEDULER MODIFIÉ EST EN TRAIN DE TOURNER ===
I0520 11:30:20.768561       1 schedule_one.go:166] "scheduling algorithm completed" duration ="7.710822ms" pod="default/mobilenet-00001-deployment-84db65c7f9-jmzrn"
I0520 11:30:22.716399       1 schedule_one.go:67] === MON SCHEDULER MODIFIÉ EST EN TRAIN DE TOURNER ===
I0520 11:30:22.719117       1 schedule_one.go:67] === MON SCHEDULER MODIFIÉ EST EN TRAIN DE TOURNER ===
I0520 11:30:22.720694       1 schedule_one.go:166] "scheduling algorithm completed" duration ="7.491211ms" pod="default/resnet-00001-deployment-5697b6d685-w8gf6"
I0520 11:30:22.721513       1 schedule_one.go:67] === MON SCHEDULER MODIFIÉ EST EN TRAIN DE TOURNER ===
I0520 11:30:22.724105       1 schedule_one.go:67] === MON SCHEDULER MODIFIÉ EST EN TRAIN DE TOURNER ===
I0520 11:30:22.725910       1 schedule_one.go:67] === MON SCHEDULER MODIFIÉ EST EN TRAIN DE TOURNER ===
I0520 11:30:22.726696       1 schedule_one.go:166] "scheduling algorithm completed" duration ="8.224211ms" pod="default/resnet-00001-deployment-5697b6d685-mxfp8"
I0520 11:30:22.727248       1 schedule_one.go:166] "scheduling algorithm completed" duration ="7.70823ms" pod="default/resnet-00001-deployment-5697b6d685-hnw6z"
I0520 11:30:22.727504       1 schedule_one.go:67] === MON SCHEDULER MODIFIÉ EST EN TRAIN DE TOURNER ===
I0520 11:30:22.729688       1 schedule_one.go:166] "scheduling algorithm completed" duration ="6.818618ms" pod="default/resnet-00001-deployment-5697b6d685-h8tkb"
I0520 11:30:22.736417       1 schedule_one.go:166] "scheduling algorithm completed" duration ="10.408547ms" pod="default/resnet-00001-deployment-5697b6d685-kwpck"
I0520 11:30:22.738384       1 schedule_one.go:166] "scheduling algorithm completed" duration ="13.169994ms" pod="default/resnet-00001-deployment-5697b6d685-cr4hk"
I0520 11:30:24.749722       1 schedule_one.go:67] === MON SCHEDULER MODIFIÉ EST EN TRAIN DE TOURNER ===
I0520 11:30:24.753997       1 schedule_one.go:67] === MON SCHEDULER MODIFIÉ EST EN TRAIN DE TOURNER ===
I0520 11:30:24.755277       1 schedule_one.go:166] "scheduling algorithm completed" duration ="6.644302ms" pod="default/resnet-00001-deployment-5697b6d685-smbxz"
I0520 11:30:24.757280       1 schedule_one.go:67] === MON SCHEDULER MODIFIÉ EST EN TRAIN DE TOURNER ===
I0520 11:30:24.758203       1 schedule_one.go:67] === MON SCHEDULER MODIFIÉ EST EN TRAIN DE TOURNER ===
I0520 11:30:24.759372       1 schedule_one.go:67] === MON SCHEDULER MODIFIÉ EST EN TRAIN DE TOURNER ===
I0520 11:30:24.760965       1 schedule_one.go:67] === MON SCHEDULER MODIFIÉ EST EN TRAIN DE TOURNER ===
I0520 11:30:24.762109       1 schedule_one.go:67] === MON SCHEDULER MODIFIÉ EST EN TRAIN DE TOURNER ===
I0520 11:30:24.762698       1 schedule_one.go:166] "scheduling algorithm completed" duration ="9.589935ms" pod="default/resnet-00001-deployment-5697b6d685-p7zhg"
I0520 11:30:24.763887       1 schedule_one.go:166] "scheduling algorithm completed" duration ="8.974768ms" pod="default/resnet-00001-deployment-5697b6d685-brdrj"
I0520 11:30:24.765215       1 schedule_one.go:166] "scheduling algorithm completed" duration ="7.890489ms" pod="default/resnet-00001-deployment-5697b6d685-w9ss4"
I0520 11:30:24.767057       1 schedule_one.go:166] "scheduling algorithm completed" duration ="6.879303ms" pod="default/resnet-00001-deployment-5697b6d685-dw6f7"
I0520 11:30:24.769258       1 schedule_one.go:67] === MON SCHEDULER MODIFIÉ EST EN TRAIN DE TOURNER ===
I0520 11:30:24.769515       1 schedule_one.go:166] "scheduling algorithm completed" duration ="10.730973ms" pod="default/resnet-00001-deployment-5697b6d685-bbn4m"
I0520 11:30:24.769807       1 schedule_one.go:166] "scheduling algorithm completed" duration ="8.300767ms" pod="default/resnet-00001-deployment-5697b6d685-gxcz4"
I0520 11:30:24.775531       1 schedule_one.go:166] "scheduling algorithm completed" duration ="7.789211ms" pod="default/resnet-00001-deployment-5697b6d685-nwrc6"
I0520 11:30:26.719335       1 schedule_one.go:67] === MON SCHEDULER MODIFIÉ EST EN TRAIN DE TOURNER ===
I0520 11:30:26.725720       1 schedule_one.go:67] === MON SCHEDULER MODIFIÉ EST EN TRAIN DE TOURNER ===
I0520 11:30:26.726748       1 schedule_one.go:166] "scheduling algorithm completed" duration ="9.11373ms" pod="default/resnet-00001-deployment-5697b6d685-dgzqc"
I0520 11:30:26.732634       1 schedule_one.go:67] === MON SCHEDULER MODIFIÉ EST EN TRAIN DE TOURNER ===
I0520 11:30:26.740051       1 schedule_one.go:166] "scheduling algorithm completed" duration ="18.971703ms" pod="default/resnet-00001-deployment-5697b6d685-zsg9p"
I0520 11:30:26.742378       1 schedule_one.go:166] "scheduling algorithm completed" duration ="16.269959ms" pod="default/resnet-00001-deployment-5697b6d685-nz8ms"
I0520 11:30:26.749102       1 schedule_one.go:67] === MON SCHEDULER MODIFIÉ EST EN TRAIN DE TOURNER ===
I0520 11:30:26.756988       1 schedule_one.go:166] "scheduling algorithm completed" duration ="24.279801ms" pod="default/resnet-00001-deployment-5697b6d685-9tk8c"
I0520 11:30:28.719697       1 schedule_one.go:67] === MON SCHEDULER MODIFIÉ EST EN TRAIN DE TOURNER ===
I0520 11:30:28.727195       1 schedule_one.go:166] "scheduling algorithm completed" duration ="8.936083ms" pod="default/resnet-00001-deployment-5697b6d685-bk6x4"
I0520 11:40:16.707164       1 schedule_one.go:67] === MON SCHEDULER MODIFIÉ EST EN TRAIN DE TOURNER ===
I0520 11:40:16.707837       1 schedule_one.go:67] === MON SCHEDULER MODIFIÉ EST EN TRAIN DE TOURNER ===
I0520 11:40:16.712583       1 schedule_one.go:166] "scheduling algorithm completed" duration ="6.102172ms" pod="default/mobilenet-00001-deployment-84db65c7f9-tps7v"
I0520 11:40:16.714045       1 schedule_one.go:166] "scheduling algorithm completed" duration ="6.77571ms" pod="default/resnet-00001-deployment-5697b6d685-zc6dj"
I0520 11:40:16.731426       1 schedule_one.go:67] === MON SCHEDULER MODIFIÉ EST EN TRAIN DE TOURNER ===
I0520 11:40:16.736482       1 schedule_one.go:166] "scheduling algorithm completed" duration ="5.608116ms" pod="default/resnet-00001-deployment-5697b6d685-d8kxq"
I0520 11:40:16.752129       1 schedule_one.go:67] === MON SCHEDULER MODIFIÉ EST EN TRAIN DE TOURNER ===
I0520 11:40:16.756975       1 schedule_one.go:166] "scheduling algorithm completed" duration ="5.472968ms" pod="default/mobilenet-00001-deployment-84db65c7f9-42vtv"
I0520 11:40:18.716344       1 schedule_one.go:67] === MON SCHEDULER MODIFIÉ EST EN TRAIN DE TOURNER ===
I0520 11:40:18.717442       1 schedule_one.go:67] === MON SCHEDULER MODIFIÉ EST EN TRAIN DE TOURNER ===
I0520 11:40:18.721024       1 schedule_one.go:67] === MON SCHEDULER MODIFIÉ EST EN TRAIN DE TOURNER ===
I0520 11:40:18.723501       1 schedule_one.go:67] === MON SCHEDULER MODIFIÉ EST EN TRAIN DE TOURNER ===
I0520 11:40:18.724485       1 schedule_one.go:67] === MON SCHEDULER MODIFIÉ EST EN TRAIN DE TOURNER ===
I0520 11:40:18.725633       1 schedule_one.go:166] "scheduling algorithm completed" duration ="9.252472ms" pod="default/mobilenet-00001-deployment-84db65c7f9-4pwqd"
I0520 11:40:18.725634       1 schedule_one.go:166] "scheduling algorithm completed" duration ="10.181417ms" pod="default/resnet-00001-deployment-5697b6d685-p5djl"
I0520 11:40:18.729597       1 schedule_one.go:67] === MON SCHEDULER MODIFIÉ EST EN TRAIN DE TOURNER ===
I0520 11:40:18.730645       1 schedule_one.go:67] === MON SCHEDULER MODIFIÉ EST EN TRAIN DE TOURNER ===
I0520 11:40:18.732830       1 schedule_one.go:67] === MON SCHEDULER MODIFIÉ EST EN TRAIN DE TOURNER ===
I0520 11:40:18.733761       1 schedule_one.go:166] "scheduling algorithm completed" duration ="13.549531ms" pod="default/resnet-00001-deployment-5697b6d685-5w67b"
I0520 11:40:18.734415       1 schedule_one.go:67] === MON SCHEDULER MODIFIÉ EST EN TRAIN DE TOURNER ===
I0520 11:40:18.735724       1 schedule_one.go:166] "scheduling algorithm completed" duration ="13.059012ms" pod="default/mobilenet-00001-deployment-84db65c7f9-b6hzn"
I0520 11:40:18.735748       1 schedule_one.go:166] "scheduling algorithm completed" duration ="11.954307ms" pod="default/mobilenet-00001-deployment-84db65c7f9-47t7b"
I0520 11:40:18.738236       1 schedule_one.go:67] === MON SCHEDULER MODIFIÉ EST EN TRAIN DE TOURNER ===
I0520 11:40:18.740223       1 schedule_one.go:67] === MON SCHEDULER MODIFIÉ EST EN TRAIN DE TOURNER ===
I0520 11:40:18.741242       1 schedule_one.go:166] "scheduling algorithm completed" duration ="11.609622ms" pod="default/mobilenet-00001-deployment-84db65c7f9-q7pmc"
I0520 11:40:18.750575       1 schedule_one.go:166] "scheduling algorithm completed" duration ="17.706405ms" pod="default/mobilenet-00001-deployment-84db65c7f9-989mm"
I0520 11:40:18.751759       1 schedule_one.go:166] "scheduling algorithm completed" duration ="19.812315ms" pod="default/mobilenet-00001-deployment-84db65c7f9-cv2df"
I0520 11:40:18.754522       1 schedule_one.go:166] "scheduling algorithm completed" duration ="17.932869ms" pod="default/resnet-00001-deployment-5697b6d685-f44xb"
I0520 11:40:18.758140       1 schedule_one.go:166] "scheduling algorithm completed" duration ="29.471787ms" pod="default/resnet-00001-deployment-5697b6d685-7nvcp"
I0520 11:40:18.773692       1 schedule_one.go:166] "scheduling algorithm completed" duration ="35.409848ms" pod="default/resnet-00001-deployment-5697b6d685-64rqd"
I0520 11:40:20.715020       1 schedule_one.go:67] === MON SCHEDULER MODIFIÉ EST EN TRAIN DE TOURNER ===
I0520 11:40:20.722520       1 schedule_one.go:67] === MON SCHEDULER MODIFIÉ EST EN TRAIN DE TOURNER ===
I0520 11:40:20.723649       1 schedule_one.go:166] "scheduling algorithm completed" duration ="9.375731ms" pod="default/resnet-00001-deployment-5697b6d685-hgq2x"
I0520 11:40:20.724718       1 schedule_one.go:67] === MON SCHEDULER MODIFIÉ EST EN TRAIN DE TOURNER ===
I0520 11:40:20.727680       1 schedule_one.go:166] "scheduling algorithm completed" duration ="6.178395ms" pod="default/resnet-00001-deployment-5697b6d685-7h48v"
I0520 11:40:20.729156       1 schedule_one.go:67] === MON SCHEDULER MODIFIÉ EST EN TRAIN DE TOURNER ===
I0520 11:40:20.729311       1 schedule_one.go:166] "scheduling algorithm completed" duration ="5.25443ms" pod="default/resnet-00001-deployment-5697b6d685-jgk2l"
I0520 11:40:20.736330       1 schedule_one.go:166] "scheduling algorithm completed" duration ="9.146083ms" pod="default/resnet-00001-deployment-5697b6d685-ckn7d"
I0520 11:40:22.721215       1 schedule_one.go:67] === MON SCHEDULER MODIFIÉ EST EN TRAIN DE TOURNER ===
I0520 11:40:22.725836       1 schedule_one.go:67] === MON SCHEDULER MODIFIÉ EST EN TRAIN DE TOURNER ===
I0520 11:40:22.728249       1 schedule_one.go:166] "scheduling algorithm completed" duration ="9.660416ms" pod="default/resnet-00001-deployment-5697b6d685-sck8n"
I0520 11:40:22.735092       1 schedule_one.go:67] === MON SCHEDULER MODIFIÉ EST EN TRAIN DE TOURNER ===
I0520 11:40:22.735710       1 schedule_one.go:166] "scheduling algorithm completed" duration ="12.475697ms" pod="default/resnet-00001-deployment-5697b6d685-xtk6j"
I0520 11:40:22.736537       1 schedule_one.go:67] === MON SCHEDULER MODIFIÉ EST EN TRAIN DE TOURNER ===
I0520 11:40:22.737612       1 schedule_one.go:67] === MON SCHEDULER MODIFIÉ EST EN TRAIN DE TOURNER ===
I0520 11:40:22.738950       1 schedule_one.go:67] === MON SCHEDULER MODIFIÉ EST EN TRAIN DE TOURNER ===
I0520 11:40:22.740106       1 schedule_one.go:67] === MON SCHEDULER MODIFIÉ EST EN TRAIN DE TOURNER ===
I0520 11:40:22.741030       1 schedule_one.go:67] === MON SCHEDULER MODIFIÉ EST EN TRAIN DE TOURNER ===
I0520 11:40:22.741491       1 schedule_one.go:166] "scheduling algorithm completed" duration ="14.769477ms" pod="default/resnet-00001-deployment-5697b6d685-dzsmz"
I0520 11:40:22.741826       1 schedule_one.go:67] === MON SCHEDULER MODIFIÉ EST EN TRAIN DE TOURNER ===
I0520 11:40:22.742515       1 schedule_one.go:166] "scheduling algorithm completed" duration ="7.38347ms" pod="default/resnet-00001-deployment-5697b6d685-gswkc"
I0520 11:40:22.743879       1 schedule_one.go:166] "scheduling algorithm completed" duration ="7.252822ms" pod="default/resnet-00001-deployment-5697b6d685-t8n82"
I0520 11:40:22.745002       1 schedule_one.go:166] "scheduling algorithm completed" duration ="7.290766ms" pod="default/resnet-00001-deployment-5697b6d685-9xcsf"
I0520 11:40:22.745125       1 schedule_one.go:166] "scheduling algorithm completed" duration ="6.075376ms" pod="default/resnet-00001-deployment-5697b6d685-7s8lq"
I0520 11:40:22.750501       1 schedule_one.go:166] "scheduling algorithm completed" duration ="9.433898ms" pod="default/resnet-00001-deployment-5697b6d685-j95j6"
I0520 11:40:22.750729       1 schedule_one.go:166] "scheduling algorithm completed" duration ="10.59101ms" pod="default/resnet-00001-deployment-5697b6d685-nt7qz"
I0520 11:40:24.712786       1 schedule_one.go:67] === MON SCHEDULER MODIFIÉ EST EN TRAIN DE TOURNER ===
I0520 11:40:24.717628       1 schedule_one.go:67] === MON SCHEDULER MODIFIÉ EST EN TRAIN DE TOURNER ===
I0520 11:40:24.719587       1 schedule_one.go:67] === MON SCHEDULER MODIFIÉ EST EN TRAIN DE TOURNER ===
I0520 11:40:24.720302       1 schedule_one.go:166] "scheduling algorithm completed" duration ="8.225563ms" pod="default/resnet-00001-deployment-5697b6d685-kr292"
I0520 11:40:24.723394       1 schedule_one.go:166] "scheduling algorithm completed" duration ="6.836025ms" pod="default/resnet-00001-deployment-5697b6d685-pvzpb"
I0520 11:40:24.724375       1 schedule_one.go:67] === MON SCHEDULER MODIFIÉ EST EN TRAIN DE TOURNER ===
I0520 11:40:24.724902       1 schedule_one.go:166] "scheduling algorithm completed" duration ="6.407173ms" pod="default/resnet-00001-deployment-5697b6d685-crsvk"
I0520 11:40:24.726617       1 schedule_one.go:67] === MON SCHEDULER MODIFIÉ EST EN TRAIN DE TOURNER ===
I0520 11:40:24.729678       1 schedule_one.go:166] "scheduling algorithm completed" duration ="6.554025ms" pod="default/resnet-00001-deployment-5697b6d685-vxcd4"
I0520 11:40:24.731584       1 schedule_one.go:166] "scheduling algorithm completed" duration ="6.274895ms" pod="default/resnet-00001-deployment-5697b6d685-n8r89"
I0520 11:40:26.715146       1 schedule_one.go:67] === MON SCHEDULER MODIFIÉ EST EN TRAIN DE TOURNER ===
I0520 11:40:26.720181       1 schedule_one.go:67] === MON SCHEDULER MODIFIÉ EST EN TRAIN DE TOURNER ===
I0520 11:40:26.720537       1 schedule_one.go:166] "scheduling algorithm completed" duration ="6.541358ms" pod="default/resnet-00001-deployment-5697b6d685-rjwjw"
I0520 11:40:26.723086       1 schedule_one.go:67] === MON SCHEDULER MODIFIÉ EST EN TRAIN DE TOURNER ===
I0520 11:40:26.725855       1 schedule_one.go:166] "scheduling algorithm completed" duration ="6.238783ms" pod="default/resnet-00001-deployment-5697b6d685-mw42l"
I0520 11:40:26.727740       1 schedule_one.go:166] "scheduling algorithm completed" duration ="5.299153ms" pod="default/resnet-00001-deployment-5697b6d685-77gjn"
