I0423 11:02:05.023071       1 serving.go:386] Generated self-signed cert in-memory
W0423 11:02:05.023663       1 client_config.go:683] Neither --kubeconfig nor --master was specified.  Using the inClusterConfig.  This might not work.
I0423 11:02:05.048088       1 scheduler.go:283] ===  SCHEDULer New  ===
I0423 11:02:05.050361       1 scheduler.go:457] "fonction New() construit le scheduler, mais ne commence pas à scheduler les pods, c'est la fonction Run() qui commence le scheduling des pods." duration ="2.235853ms"
I0423 11:02:05.053493       1 server.go:175] "Starting Kubernetes Scheduler" version="v0.0.0-master+$Format:%H$"
I0423 11:02:05.053515       1 server.go:177] "Golang settings" GOGC="" GOMAXPROCS="" GOTRACEBACK=""
I0423 11:02:05.060280       1 requestheader_controller.go:180] Starting RequestHeaderAuthRequestController
I0423 11:02:05.060301       1 shared_informer.go:375] "Waiting for caches to sync"
I0423 11:02:05.060342       1 configmap_cafile_content.go:205] "Starting controller" name="client-ca::kube-system::extension-apiserver-authentication::client-ca-file"
I0423 11:02:05.060350       1 shared_informer.go:375] "Waiting for caches to sync"
I0423 11:02:05.060350       1 configmap_cafile_content.go:205] "Starting controller" name="client-ca::kube-system::extension-apiserver-authentication::requestheader-client-ca-file"
I0423 11:02:05.060361       1 shared_informer.go:375] "Waiting for caches to sync"
I0423 11:02:05.060517       1 secure_serving.go:211] Serving securely on [::]:10259
I0423 11:02:05.060582       1 tlsconfig.go:243] "Starting DynamicServingCertificateController"
I0423 11:02:05.261101       1 shared_informer.go:382] "Caches are synced"
I0423 11:02:05.261118       1 shared_informer.go:382] "Caches are synced"
I0423 11:02:05.261112       1 shared_informer.go:382] "Caches are synced"
I0423 11:02:05.261191       1 scheduler.go:542] ===  SCHEDULing RUN ===
I0423 11:02:05.261235       1 schedule_one.go:67] === MON SCHEDULER MODIFIÉ EST EN TRAIN DE TOURNER ===
I0423 11:06:09.164227       1 schedule_one.go:67] === MON SCHEDULER MODIFIÉ EST EN TRAIN DE TOURNER ===
I0423 11:06:09.165437       1 schedule_one.go:67] === MON SCHEDULER MODIFIÉ EST EN TRAIN DE TOURNER ===
I0423 11:06:09.166155       1 schedule_one.go:67] === MON SCHEDULER MODIFIÉ EST EN TRAIN DE TOURNER ===
I0423 11:06:09.167557       1 schedule_one.go:67] === MON SCHEDULER MODIFIÉ EST EN TRAIN DE TOURNER ===
I0423 11:06:09.175829       1 schedule_one.go:166] "scheduling algorithm completed" duration ="11.558413ms" pod="default/fastfouriertransform-00001-deployment-657cc65f49-scfmv"
I0423 11:06:09.175873       1 schedule_one.go:166] "scheduling algorithm completed" duration ="13.849765ms" pod="default/grayscale-00001-deployment-5bdd67fc57-dkg4d"
I0423 11:06:09.177456       1 schedule_one.go:166] "scheduling algorithm completed" duration ="11.983598ms" pod="default/genmatrix-00001-deployment-5df4b84798-4zknq"
I0423 11:06:09.182591       1 schedule_one.go:166] "scheduling algorithm completed" duration ="16.365489ms" pod="default/pagerank-00001-deployment-5868dc586f-97k22"
I0423 11:06:10.120626       1 schedule_one.go:67] === MON SCHEDULER MODIFIÉ EST EN TRAIN DE TOURNER ===
I0423 11:06:10.127103       1 schedule_one.go:67] === MON SCHEDULER MODIFIÉ EST EN TRAIN DE TOURNER ===
I0423 11:06:10.128843       1 schedule_one.go:67] === MON SCHEDULER MODIFIÉ EST EN TRAIN DE TOURNER ===
I0423 11:06:10.130828       1 schedule_one.go:166] "scheduling algorithm completed" duration ="10.984876ms" pod="default/resnet-00001-deployment-58d467dc88-pwjg8"
I0423 11:06:10.131879       1 schedule_one.go:166] "scheduling algorithm completed" duration ="5.781428ms" pod="default/fastfouriertransform-00001-deployment-657cc65f49-9rxs2"
I0423 11:06:10.137458       1 schedule_one.go:166] "scheduling algorithm completed" duration ="9.630283ms" pod="default/resnet-00001-deployment-58d467dc88-jrmg4"
I0423 11:06:10.150823       1 schedule_one.go:67] === MON SCHEDULER MODIFIÉ EST EN TRAIN DE TOURNER ===
I0423 11:06:10.162419       1 schedule_one.go:166] "scheduling algorithm completed" duration ="12.407302ms" pod="default/mobilenet-00001-deployment-799ff7446f-w6dfb"
I0423 11:06:10.222742       1 schedule_one.go:67] === MON SCHEDULER MODIFIÉ EST EN TRAIN DE TOURNER ===
I0423 11:06:10.227241       1 schedule_one.go:166] "scheduling algorithm completed" duration ="6.431892ms" pod="default/fetchdata-00001-deployment-6f7fd5c6-x5ldv"
I0423 11:06:10.419439       1 schedule_one.go:67] === MON SCHEDULER MODIFIÉ EST EN TRAIN DE TOURNER ===
I0423 11:06:10.424529       1 schedule_one.go:166] "scheduling algorithm completed" duration ="6.379651ms" pod="default/graphgen-00001-deployment-6f84b8d49c-sxmt4"
I0423 11:06:10.767254       1 schedule_one.go:67] === MON SCHEDULER MODIFIÉ EST EN TRAIN DE TOURNER ===
I0423 11:06:10.771780       1 schedule_one.go:166] "scheduling algorithm completed" duration ="5.466299ms" pod="default/linpack-00001-deployment-5786f975fd-btxrl"
I0423 11:06:10.966872       1 schedule_one.go:67] === MON SCHEDULER MODIFIÉ EST EN TRAIN DE TOURNER ===
I0423 11:06:10.972205       1 schedule_one.go:166] "scheduling algorithm completed" duration ="5.926688ms" pod="default/matrixmul-00001-deployment-7bd6bb5956-qhq42"
I0423 11:06:12.123019       1 schedule_one.go:67] === MON SCHEDULER MODIFIÉ EST EN TRAIN DE TOURNER ===
I0423 11:06:12.127910       1 schedule_one.go:166] "scheduling algorithm completed" duration ="5.632059ms" pod="default/linpack-00001-deployment-5786f975fd-69947"
I0423 11:06:14.124362       1 schedule_one.go:67] === MON SCHEDULER MODIFIÉ EST EN TRAIN DE TOURNER ===
I0423 11:06:14.128113       1 schedule_one.go:67] === MON SCHEDULER MODIFIÉ EST EN TRAIN DE TOURNER ===
I0423 11:06:14.133296       1 schedule_one.go:166] "scheduling algorithm completed" duration ="9.533894ms" pod="default/graphgen-00001-deployment-6f84b8d49c-njg4z"
I0423 11:06:14.133793       1 schedule_one.go:166] "scheduling algorithm completed" duration ="6.213336ms" pod="default/grayscale-00001-deployment-5bdd67fc57-zzjm2"
I0423 11:06:16.123827       1 schedule_one.go:67] === MON SCHEDULER MODIFIÉ EST EN TRAIN DE TOURNER ===
I0423 11:06:16.127219       1 schedule_one.go:67] === MON SCHEDULER MODIFIÉ EST EN TRAIN DE TOURNER ===
I0423 11:06:16.132523       1 schedule_one.go:166] "scheduling algorithm completed" duration ="9.327227ms" pod="default/grayscale-00001-deployment-5bdd67fc57-s5wgj"
I0423 11:06:16.163369       1 schedule_one.go:67] === MON SCHEDULER MODIFIÉ EST EN TRAIN DE TOURNER ===
I0423 11:06:16.167725       1 schedule_one.go:166] "scheduling algorithm completed" duration ="5.164947ms" pod="default/matrixmul-00001-deployment-7bd6bb5956-x54f8"
I0423 11:06:16.175225       1 schedule_one.go:166] "scheduling algorithm completed" duration ="48.682227ms" pod="default/graphgen-00001-deployment-6f84b8d49c-df6dr"
I0423 11:06:18.120305       1 schedule_one.go:67] === MON SCHEDULER MODIFIÉ EST EN TRAIN DE TOURNER ===
I0423 11:06:18.124974       1 schedule_one.go:166] "scheduling algorithm completed" duration ="5.362318ms" pod="default/grayscale-00001-deployment-5bdd67fc57-dndcz"
I0423 11:06:22.122108       1 schedule_one.go:67] === MON SCHEDULER MODIFIÉ EST EN TRAIN DE TOURNER ===
I0423 11:06:22.127541       1 schedule_one.go:166] "scheduling algorithm completed" duration ="6.100577ms" pod="default/grayscale-00001-deployment-5bdd67fc57-52rkr"
I0423 11:07:28.175397       1 schedule_one.go:67] === MON SCHEDULER MODIFIÉ EST EN TRAIN DE TOURNER ===
I0423 11:07:28.179819       1 schedule_one.go:166] "scheduling algorithm completed" duration ="5.067336ms" pod="default/matrixmul-00001-deployment-7bd6bb5956-l7v97"
I0423 11:07:34.123562       1 schedule_one.go:67] === MON SCHEDULER MODIFIÉ EST EN TRAIN DE TOURNER ===
I0423 11:07:34.128914       1 schedule_one.go:166] "scheduling algorithm completed" duration ="6.000911ms" pod="default/grayscale-00001-deployment-5bdd67fc57-s9hnt"
I0423 11:07:38.121550       1 schedule_one.go:67] === MON SCHEDULER MODIFIÉ EST EN TRAIN DE TOURNER ===
I0423 11:07:38.125827       1 schedule_one.go:166] "scheduling algorithm completed" duration ="4.81115ms" pod="default/grayscale-00001-deployment-5bdd67fc57-gfrwm"
I0423 11:12:10.315200       1 schedule_one.go:67] === MON SCHEDULER MODIFIÉ EST EN TRAIN DE TOURNER ===
I0423 11:12:10.318714       1 schedule_one.go:67] === MON SCHEDULER MODIFIÉ EST EN TRAIN DE TOURNER ===
I0423 11:12:10.321159       1 schedule_one.go:166] "scheduling algorithm completed" duration ="6.82819ms" pod="default/fastfouriertransform-00001-deployment-657cc65f49-l47w7"
I0423 11:12:10.325259       1 schedule_one.go:166] "scheduling algorithm completed" duration ="7.391449ms" pod="default/grayscale-00001-deployment-5bdd67fc57-r6rc5"
I0423 11:12:10.370125       1 schedule_one.go:67] === MON SCHEDULER MODIFIÉ EST EN TRAIN DE TOURNER ===
I0423 11:12:10.374893       1 schedule_one.go:166] "scheduling algorithm completed" duration ="5.580504ms" pod="default/genmatrix-00001-deployment-5df4b84798-b7kz8"
I0423 11:12:10.473656       1 schedule_one.go:67] === MON SCHEDULER MODIFIÉ EST EN TRAIN DE TOURNER ===
I0423 11:12:10.477686       1 schedule_one.go:166] "scheduling algorithm completed" duration ="4.667596ms" pod="default/pagerank-00001-deployment-5868dc586f-c5cvh"
I0423 11:12:10.534797       1 schedule_one.go:67] === MON SCHEDULER MODIFIÉ EST EN TRAIN DE TOURNER ===
I0423 11:12:10.539547       1 schedule_one.go:166] "scheduling algorithm completed" duration ="5.719263ms" pod="default/resnet-00001-deployment-58d467dc88-2x5s2"
I0423 11:12:10.755475       1 schedule_one.go:67] === MON SCHEDULER MODIFIÉ EST EN TRAIN DE TOURNER ===
I0423 11:12:10.768181       1 schedule_one.go:166] "scheduling algorithm completed" duration ="13.430805ms" pod="default/graphgen-00001-deployment-6f84b8d49c-smqrd"
I0423 11:12:11.132486       1 schedule_one.go:67] === MON SCHEDULER MODIFIÉ EST EN TRAIN DE TOURNER ===
I0423 11:12:11.138214       1 schedule_one.go:166] "scheduling algorithm completed" duration ="6.635874ms" pod="default/matrixmul-00001-deployment-7bd6bb5956-g5k7r"
I0423 11:12:11.482423       1 schedule_one.go:67] === MON SCHEDULER MODIFIÉ EST EN TRAIN DE TOURNER ===
I0423 11:12:11.487750       1 schedule_one.go:166] "scheduling algorithm completed" duration ="6.143653ms" pod="default/linpack-00001-deployment-5786f975fd-wd9p5"
I0423 11:12:11.689361       1 schedule_one.go:67] === MON SCHEDULER MODIFIÉ EST EN TRAIN DE TOURNER ===
I0423 11:12:11.701386       1 schedule_one.go:166] "scheduling algorithm completed" duration ="17.6789ms" pod="default/mobilenet-00001-deployment-799ff7446f-6cqw4"
I0423 11:12:12.385861       1 schedule_one.go:67] === MON SCHEDULER MODIFIÉ EST EN TRAIN DE TOURNER ===
I0423 11:12:12.390555       1 schedule_one.go:166] "scheduling algorithm completed" duration ="5.61204ms" pod="default/fastfouriertransform-00001-deployment-657cc65f49-xngfx"
I0423 11:12:12.432448       1 schedule_one.go:67] === MON SCHEDULER MODIFIÉ EST EN TRAIN DE TOURNER ===
I0423 11:12:12.437008       1 schedule_one.go:166] "scheduling algorithm completed" duration ="5.321819ms" pod="default/fetchdata-00001-deployment-6f7fd5c6-9pb9p"
I0423 11:12:14.124276       1 schedule_one.go:67] === MON SCHEDULER MODIFIÉ EST EN TRAIN DE TOURNER ===
I0423 11:12:14.129973       1 schedule_one.go:166] "scheduling algorithm completed" duration ="6.581319ms" pod="default/linpack-00001-deployment-5786f975fd-f2p2l"
I0423 11:12:16.120730       1 schedule_one.go:67] === MON SCHEDULER MODIFIÉ EST EN TRAIN DE TOURNER ===
I0423 11:12:16.124991       1 schedule_one.go:166] "scheduling algorithm completed" duration ="4.90741ms" pod="default/grayscale-00001-deployment-5bdd67fc57-s56qt"
I0423 11:12:18.119467       1 schedule_one.go:67] === MON SCHEDULER MODIFIÉ EST EN TRAIN DE TOURNER ===
I0423 11:12:18.126320       1 schedule_one.go:166] "scheduling algorithm completed" duration ="7.542653ms" pod="default/grayscale-00001-deployment-5bdd67fc57-kwz84"
I0423 11:12:28.129912       1 schedule_one.go:67] === MON SCHEDULER MODIFIÉ EST EN TRAIN DE TOURNER ===
I0423 11:12:28.134725       1 schedule_one.go:166] "scheduling algorithm completed" duration ="5.73354ms" pod="default/grayscale-00001-deployment-5bdd67fc57-4dp72"
I0423 11:12:32.128843       1 schedule_one.go:67] === MON SCHEDULER MODIFIÉ EST EN TRAIN DE TOURNER ===
I0423 11:12:32.132470       1 schedule_one.go:166] "scheduling algorithm completed" duration ="4.216039ms" pod="default/matrixmul-00001-deployment-7bd6bb5956-v7rgj"
I0423 11:18:42.833917       1 schedule_one.go:67] === MON SCHEDULER MODIFIÉ EST EN TRAIN DE TOURNER ===
I0423 11:18:42.836439       1 schedule_one.go:67] === MON SCHEDULER MODIFIÉ EST EN TRAIN DE TOURNER ===
I0423 11:18:42.838364       1 schedule_one.go:67] === MON SCHEDULER MODIFIÉ EST EN TRAIN DE TOURNER ===
I0423 11:18:42.842713       1 schedule_one.go:166] "scheduling algorithm completed" duration ="9.497396ms" pod="default/grayscale-00001-deployment-5bdd67fc57-d4lz4"
I0423 11:18:42.843308       1 schedule_one.go:166] "scheduling algorithm completed" duration ="7.412617ms" pod="default/fastfouriertransform-00001-deployment-657cc65f49-rpxpk"
I0423 11:18:42.847734       1 schedule_one.go:166] "scheduling algorithm completed" duration ="10.246322ms" pod="default/genmatrix-00001-deployment-5df4b84798-fffsq"
I0423 11:18:42.925057       1 schedule_one.go:67] === MON SCHEDULER MODIFIÉ EST EN TRAIN DE TOURNER ===
I0423 11:18:42.929345       1 schedule_one.go:166] "scheduling algorithm completed" duration ="4.851189ms" pod="default/pagerank-00001-deployment-5868dc586f-2xt5w"
I0423 11:18:42.975828       1 schedule_one.go:67] === MON SCHEDULER MODIFIÉ EST EN TRAIN DE TOURNER ===
I0423 11:18:42.980606       1 schedule_one.go:166] "scheduling algorithm completed" duration ="5.3648ms" pod="default/resnet-00001-deployment-58d467dc88-g65qq"
I0423 11:18:43.138866       1 schedule_one.go:67] === MON SCHEDULER MODIFIÉ EST EN TRAIN DE TOURNER ===
I0423 11:18:43.144290       1 schedule_one.go:166] "scheduling algorithm completed" duration ="5.988597ms" pod="default/graphgen-00001-deployment-6f84b8d49c-lshpc"
I0423 11:18:43.534282       1 schedule_one.go:67] === MON SCHEDULER MODIFIÉ EST EN TRAIN DE TOURNER ===
I0423 11:18:43.538703       1 schedule_one.go:166] "scheduling algorithm completed" duration ="5.014874ms" pod="default/matrixmul-00001-deployment-7bd6bb5956-b4bwb"
I0423 11:18:43.833088       1 schedule_one.go:67] === MON SCHEDULER MODIFIÉ EST EN TRAIN DE TOURNER ===
I0423 11:18:43.837023       1 schedule_one.go:166] "scheduling algorithm completed" duration ="4.599114ms" pod="default/linpack-00001-deployment-5786f975fd-pd7kc"
I0423 11:18:44.134665       1 schedule_one.go:67] === MON SCHEDULER MODIFIÉ EST EN TRAIN DE TOURNER ===
I0423 11:18:44.139177       1 schedule_one.go:166] "scheduling algorithm completed" duration ="5.1748ms" pod="default/mobilenet-00001-deployment-799ff7446f-rhp8l"
I0423 11:18:44.885959       1 schedule_one.go:67] === MON SCHEDULER MODIFIÉ EST EN TRAIN DE TOURNER ===
I0423 11:18:44.890427       1 schedule_one.go:166] "scheduling algorithm completed" duration ="5.104263ms" pod="default/fetchdata-00001-deployment-6f7fd5c6-pw7qh"
I0423 11:18:48.128813       1 schedule_one.go:67] === MON SCHEDULER MODIFIÉ EST EN TRAIN DE TOURNER ===
I0423 11:18:48.134028       1 schedule_one.go:166] "scheduling algorithm completed" duration ="6.045875ms" pod="default/grayscale-00001-deployment-5bdd67fc57-krl6l"
I0423 11:18:50.129690       1 schedule_one.go:67] === MON SCHEDULER MODIFIÉ EST EN TRAIN DE TOURNER ===
I0423 11:18:50.130882       1 schedule_one.go:67] === MON SCHEDULER MODIFIÉ EST EN TRAIN DE TOURNER ===
I0423 11:18:50.142490       1 schedule_one.go:166] "scheduling algorithm completed" duration ="13.490214ms" pod="default/grayscale-00001-deployment-5bdd67fc57-nz5xh"
I0423 11:18:50.145007       1 schedule_one.go:166] "scheduling algorithm completed" duration ="14.810289ms" pod="default/linpack-00001-deployment-5786f975fd-4wpv5"
I0423 11:19:04.118598       1 schedule_one.go:67] === MON SCHEDULER MODIFIÉ EST EN TRAIN DE TOURNER ===
I0423 11:19:04.123110       1 schedule_one.go:166] "scheduling algorithm completed" duration ="5.090318ms" pod="default/matrixmul-00001-deployment-7bd6bb5956-mc8jn"
I0423 11:19:08.123447       1 schedule_one.go:67] === MON SCHEDULER MODIFIÉ EST EN TRAIN DE TOURNER ===
I0423 11:19:08.128337       1 schedule_one.go:166] "scheduling algorithm completed" duration ="5.444596ms" pod="default/grayscale-00001-deployment-5bdd67fc57-p976r"
I0423 11:19:22.133921       1 schedule_one.go:67] === MON SCHEDULER MODIFIÉ EST EN TRAIN DE TOURNER ===
I0423 11:19:22.138698       1 schedule_one.go:166] "scheduling algorithm completed" duration ="5.514559ms" pod="default/fastfouriertransform-00001-deployment-657cc65f49-gqzw8"
I0423 11:20:20.136088       1 schedule_one.go:67] === MON SCHEDULER MODIFIÉ EST EN TRAIN DE TOURNER ===
I0423 11:20:20.141187       1 schedule_one.go:67] === MON SCHEDULER MODIFIÉ EST EN TRAIN DE TOURNER ===
I0423 11:20:20.142860       1 schedule_one.go:166] "scheduling algorithm completed" duration ="7.361802ms" pod="default/grayscale-00001-deployment-5bdd67fc57-c9zsk"
I0423 11:20:20.144096       1 schedule_one.go:166] "scheduling algorithm completed" duration ="3.517299ms" pod="default/grayscale-00001-deployment-5bdd67fc57-pqp2r"
