I0520 12:37:15.589005       1 serving.go:386] Generated self-signed cert in-memory
W0520 12:37:15.589630       1 client_config.go:683] Neither --kubeconfig nor --master was specified.  Using the inClusterConfig.  This might not work.
I0520 12:37:15.615311       1 scheduler.go:283] ===  SCHEDULer New  ===
I0520 12:37:15.617119       1 scheduler.go:457] "fonction New() construit le scheduler, mais ne commence pas à scheduler les pods, c'est la fonction Run() qui commence le scheduling des pods." duration ="1.736186ms"
I0520 12:37:15.619120       1 server.go:175] "Starting Kubernetes Scheduler" version="v0.0.0-master+$Format:%H$"
I0520 12:37:15.619169       1 server.go:177] "Golang settings" GOGC="" GOMAXPROCS="" GOTRACEBACK=""
I0520 12:37:15.626034       1 requestheader_controller.go:180] Starting RequestHeaderAuthRequestController
I0520 12:37:15.626137       1 shared_informer.go:375] "Waiting for caches to sync"
I0520 12:37:15.626121       1 configmap_cafile_content.go:205] "Starting controller" name="client-ca::kube-system::extension-apiserver-authentication::requestheader-client-ca-file"
I0520 12:37:15.626216       1 shared_informer.go:375] "Waiting for caches to sync"
I0520 12:37:15.626248       1 secure_serving.go:211] Serving securely on [::]:10259
I0520 12:37:15.626105       1 configmap_cafile_content.go:205] "Starting controller" name="client-ca::kube-system::extension-apiserver-authentication::client-ca-file"
I0520 12:37:15.627290       1 shared_informer.go:375] "Waiting for caches to sync"
I0520 12:37:15.626313       1 tlsconfig.go:243] "Starting DynamicServingCertificateController"
I0520 12:37:15.826493       1 shared_informer.go:382] "Caches are synced"
I0520 12:37:15.826531       1 scheduler.go:542] ===  SCHEDULing RUN ===
I0520 12:37:15.826493       1 shared_informer.go:382] "Caches are synced"
I0520 12:37:15.826577       1 schedule_one.go:67] === MON SCHEDULER MODIFIÉ EST EN TRAIN DE TOURNER ===
I0520 12:37:15.827772       1 shared_informer.go:382] "Caches are synced"
I0520 12:40:54.756536       1 schedule_one.go:67] === MON SCHEDULER MODIFIÉ EST EN TRAIN DE TOURNER ===
I0520 12:40:54.757874       1 schedule_one.go:67] === MON SCHEDULER MODIFIÉ EST EN TRAIN DE TOURNER ===
I0520 12:40:54.761976       1 schedule_one.go:166] "scheduling algorithm completed" duration ="7.165722ms" pod="default/mobilenet-00001-deployment-84db65c7f9-7tmww"
I0520 12:40:54.763193       1 schedule_one.go:166] "scheduling algorithm completed" duration ="6.064556ms" pod="default/resnet-00001-deployment-5697b6d685-vpx66"
I0520 12:40:56.234127       1 schedule_one.go:67] === MON SCHEDULER MODIFIÉ EST EN TRAIN DE TOURNER ===
I0520 12:40:56.235402       1 schedule_one.go:67] === MON SCHEDULER MODIFIÉ EST EN TRAIN DE TOURNER ===
I0520 12:40:56.237119       1 schedule_one.go:67] === MON SCHEDULER MODIFIÉ EST EN TRAIN DE TOURNER ===
I0520 12:40:56.238525       1 schedule_one.go:67] === MON SCHEDULER MODIFIÉ EST EN TRAIN DE TOURNER ===
I0520 12:40:56.239694       1 schedule_one.go:166] "scheduling algorithm completed" duration ="6.701056ms" pod="default/mobilenet-00001-deployment-84db65c7f9-qsmdf"
I0520 12:40:56.241425       1 schedule_one.go:166] "scheduling algorithm completed" duration ="7.244518ms" pod="default/resnet-00001-deployment-5697b6d685-2gnw7"
I0520 12:40:56.245104       1 schedule_one.go:166] "scheduling algorithm completed" duration ="8.960741ms" pod="default/mobilenet-00001-deployment-84db65c7f9-7g4x8"
I0520 12:40:56.249286       1 schedule_one.go:166] "scheduling algorithm completed" duration ="11.42876ms" pod="default/resnet-00001-deployment-5697b6d685-frjpq"
I0520 12:40:58.234105       1 schedule_one.go:67] === MON SCHEDULER MODIFIÉ EST EN TRAIN DE TOURNER ===
I0520 12:40:58.236607       1 schedule_one.go:67] === MON SCHEDULER MODIFIÉ EST EN TRAIN DE TOURNER ===
I0520 12:40:58.240038       1 schedule_one.go:166] "scheduling algorithm completed" duration ="6.748518ms" pod="default/mobilenet-00001-deployment-84db65c7f9-qsrkg"
I0520 12:40:58.240990       1 schedule_one.go:67] === MON SCHEDULER MODIFIÉ EST EN TRAIN DE TOURNER ===
I0520 12:40:58.242359       1 schedule_one.go:166] "scheduling algorithm completed" duration ="6.647056ms" pod="default/resnet-00001-deployment-5697b6d685-4c8nb"
I0520 12:40:58.244615       1 schedule_one.go:67] === MON SCHEDULER MODIFIÉ EST EN TRAIN DE TOURNER ===
I0520 12:40:58.245984       1 schedule_one.go:67] === MON SCHEDULER MODIFIÉ EST EN TRAIN DE TOURNER ===
I0520 12:40:58.247025       1 schedule_one.go:166] "scheduling algorithm completed" duration ="7.004ms" pod="default/mobilenet-00001-deployment-84db65c7f9-ngbbl"
I0520 12:40:58.250474       1 schedule_one.go:166] "scheduling algorithm completed" duration ="6.892185ms" pod="default/resnet-00001-deployment-5697b6d685-qt46b"
I0520 12:40:58.250963       1 schedule_one.go:166] "scheduling algorithm completed" duration ="6.305352ms" pod="default/resnet-00001-deployment-5697b6d685-q85l5"
I0520 12:41:00.235465       1 schedule_one.go:67] === MON SCHEDULER MODIFIÉ EST EN TRAIN DE TOURNER ===
I0520 12:41:00.239032       1 schedule_one.go:67] === MON SCHEDULER MODIFIÉ EST EN TRAIN DE TOURNER ===
I0520 12:41:00.241325       1 schedule_one.go:67] === MON SCHEDULER MODIFIÉ EST EN TRAIN DE TOURNER ===
I0520 12:41:00.243914       1 schedule_one.go:166] "scheduling algorithm completed" duration ="5.637092ms" pod="default/resnet-00001-deployment-5697b6d685-4z2j4"
I0520 12:41:00.244270       1 schedule_one.go:67] === MON SCHEDULER MODIFIÉ EST EN TRAIN DE TOURNER ===
I0520 12:41:00.245968       1 schedule_one.go:166] "scheduling algorithm completed" duration ="5.468815ms" pod="default/resnet-00001-deployment-5697b6d685-vw9th"
I0520 12:41:00.249591       1 schedule_one.go:166] "scheduling algorithm completed" duration ="6.207075ms" pod="default/resnet-00001-deployment-5697b6d685-wbctb"
I0520 12:41:00.270760       1 schedule_one.go:166] "scheduling algorithm completed" duration ="36.124315ms" pod="default/resnet-00001-deployment-5697b6d685-2n84c"
I0520 12:42:10.262123       1 schedule_one.go:67] === MON SCHEDULER MODIFIÉ EST EN TRAIN DE TOURNER ===
I0520 12:42:10.265301       1 schedule_one.go:67] === MON SCHEDULER MODIFIÉ EST EN TRAIN DE TOURNER ===
I0520 12:42:10.267621       1 schedule_one.go:166] "scheduling algorithm completed" duration ="6.407796ms" pod="default/resnet-00001-deployment-5697b6d685-glbcs"
I0520 12:42:10.270417       1 schedule_one.go:166] "scheduling algorithm completed" duration ="6.019037ms" pod="default/resnet-00001-deployment-5697b6d685-dxwrq"
I0520 12:42:12.233608       1 schedule_one.go:67] === MON SCHEDULER MODIFIÉ EST EN TRAIN DE TOURNER ===
I0520 12:42:12.237915       1 schedule_one.go:67] === MON SCHEDULER MODIFIÉ EST EN TRAIN DE TOURNER ===
I0520 12:42:12.239238       1 schedule_one.go:166] "scheduling algorithm completed" duration ="6.529093ms" pod="default/resnet-00001-deployment-5697b6d685-5rjj9"
I0520 12:42:12.242495       1 schedule_one.go:166] "scheduling algorithm completed" duration ="5.523555ms" pod="default/resnet-00001-deployment-5697b6d685-ns9dr"
I0520 12:42:14.234797       1 schedule_one.go:67] === MON SCHEDULER MODIFIÉ EST EN TRAIN DE TOURNER ===
I0520 12:42:14.240220       1 schedule_one.go:166] "scheduling algorithm completed" duration ="6.210741ms" pod="default/resnet-00001-deployment-5697b6d685-jshhn"
